Workbook

Sheet Сводка
A1: LEGITIMUS · Verified Partners Database (Агент 02: Partnership Intelligence Analyst)
A2: Дата проверки: 2026-10-08. Источник для проверки: база агента 01 (Legitimus_partners_research.xlsx).
A4: Статус | B4: Кол-во
A5: TOP-10 · Приоритет 1 | B5: =COUNTIF('Verified Database'!$E:$E,A5) -> 5
A6: TOP-10 · Приоритет 2 | B6: =COUNTIF('Verified Database'!$E:$E,A6) -> 5
A7: Отложено: требуется комплаенс-проверка | B7: =COUNTIF('Verified Database'!$E:$E,A7) -> 1
A8: Резерв | B8: =COUNTIF('Verified Database'!$E:$E,A8) -> 2
A9: Исключено | B9: =COUNTIF('Verified Database'!$E:$E,A9) -> 7
A10: Всего | B10: =SUM(B5:B9) -> 20
A12: Шкала оценки (100 баллов)
A13: Соответствие целевому профилю LEGITIMUS | B13: 20
A14: Потенциал клиентов на постоянное обслуживание | B14: 30
A15: Возможность сотрудничества с местным юр. партнёром | B15: 20
A16: Коммерческий интерес к Молдове | B16: 15
A17: Доступность лиц, принимающих решения | B17: 15
A18: Максимум | B18: =SUM(B13:B17) -> 100
A20: Уровни достоверности: High = текст официального сайта или реестра; Medium = сниппет с официального домена или из авторитетной прессы; Low = сторонний каталог или косвенные данные.
A21: «ASSUMPTION» = аналитическое допущение, не факт. «not found» означает, что сведения не найдены, а не что их нет.
A22: ОГРАНИЧЕНИЕ: сетевая политика среды блокировала открытие сайтов компаний. Проверка шла через поисковую выдачу (site:-запросы к официальным доменам, пресс-релизы, отраслевые СМИ). Перед контактом сверьте ключевые факты на сайтах.
A23: Баллы (синие) — экспертная оценка агента 02 с обоснованием в соседних столбцах. Их можно менять: итог и ранг пересчитаются.
A24: GSL набрал 65 баллов, но выведен из TOP-10 до формальной проверки по санкционным спискам (решение аналитика). Его место занял Virtuzone (59).
A25: Никаких контактов с компаниями не было: письма не отправлялись, формы не заполнялись.

Sheet Verified Database
A1: Ранг | B1: Компания | C1: Сайт | D1: Штаб-квартира | E1: Статус | F1: Профиль /20 | G1: Пост. клиенты /30 | H1: Локальный партнёр /20 | I1: Интерес к Молдове /15 | J1: Доступность ЛПР /15 | K1: ИТОГО /100 | L1: Оценка агента 01 (×20, индикативно) | M1: Δ к агенту 01 | N1: Обоснование оценок | O1: Существует / активна | P1: Специализация | Q1: Регистрация в нескольких странах | R1: Молдова | S1: Как оказывается в Молдове | T1: Доказательства по Молдове | U1: Достоверность (Молдова) | V1: Источники (Молдова) | W1: Сотрудничество с юрфирмами | X1: Долгосрочные услуги | Y1: Признаки разовых продаж | Z1: Email | AA1: Телефон | AB1: Страница контактов | AC1: Контакты актуальны? | AD1: Достоверность (контакты) | AE1: ЛПР (имя, должность, источник, достоверность) | AF1: Причина исключения | AG1: Дата проверки
A2: =RANK(K2,$K$2:$K$21)+COUNTIF($K$2:K2,K2)-1 -> 1 | B2: Accace | C2: https://accace.com | D2: Bratislava, Slovakia | E2: TOP-10 · Приоритет 1 | F2: 18 | G2: 26 | H2: 16 | I2: 12 | J2: 10 | K2: =SUM(F2:J2) -> 82 | L2: 89 | M2: =K2-L2 -> -7 | N2: profile_fit: Multi-country corporate/accounting/payroll provider with CEE focus and an operating partner network - closest profile to Legitimus's target. recurring_client_potential: Recurring outsourcing clients (mid-size and Fortune 500) entering CEE generate ongoing legal needs (corporate changes, employment, contracts). local_legal_partner_cooperation: Explicit partner network (Accace Circle) covers non-office jurisdictions; but it is BPO/advisor-oriented, legal partner role not explicitly advertised. moldova_commercial_interest: Already markets Moldova services with no visible own office - a real delivery-partner need, though an incumbent Moldovan provider may exist. decision_maker_accessibility: Named CEO and named Circle BD & Community Lead on own domain; no direct verified email/phone. | O2: yes - active; indexed live pages incl. Moldova service pages and Accace Circle site; leadership page live — [Medium] https://www.accace.com/locations/moldova/corporate-and-secretarial-services/ https://circle.accace.com/ https://www.accace.com/about-us/meet-our-key-people/ | P2: CEE-rooted BPO/outsourcing: corporate & secretarial, accounting & reporting, payroll/HR, tax, market entry; tax and legal experts engaged across network | Q2: yes — Accace Circle states coverage of 60+ jurisdictions / 7,000+ professionals (search summary of circle.accace.com); older Accace pages say ~40 (2020) and AmCham RO profile says 50+. Own offices only in a subset (CZ, HU, PL, RO, SK, ZA, UA, UK per theorg.com); other locations 'covered via Accace's trusted network of partners'. [Medium] https://circle.accace.com/ https://accace.com/accace-circle-new-markets-within-your-reach-press-release/ https://www.amcham.ro/company/accace-outsourcing https://theorg.com/org/accace | R2: offered | S2: unclear | T2: Dedicated page 'Corporate and secretarial services in Moldova' indexed on accace.com (company setup, tax registration, permits). No Chisinau office address found; Moldova not in the own-office list (theorg.com). ASSUMPTION: Moldova is likely delivered through a Circle/partner provider, not an own entity. | U2: Medium | V2: https://www.accace.com/locations/moldova/corporate-and-secretarial-services/ https://theorg.com/org/accace | W2: partial - network of BPO providers and advisors (Accace Circle), not a law-firm network — Accace Circle = 'co-created business community of like-minded BPO providers and advisors' under one account management; Business Development & Community Lead named. Legal experts referenced but law firms are not explicitly the core membership. [Medium] https://circle.accace.com/ https://circle.accace.com/?p=205 https://accace.com/accace-circle-new-markets-within-your-reach-press-release/ | X2: yes — Accounting & reporting, payroll/HR, corporate secretarial, tax; Moldova accounting page indexed (per agent 01; not re-surfaced this run). https://www.accace.com/locations/moldova/corporate-and-secretarial-services/ https://accace.com/accace-circle-new-markets-within-your-reach-press-release/ | Y2: None found - positioning is ongoing outsourcing (accounting, payroll, secretarial). | Z2: not verified on own domain (agent 01 directory emails slovakia@accace.com / czechrepublic@accace.com remain unverified) | AA2: not verified on own domain | AB2: not verified (accace.com unreachable: ENOTFOUND) | AC2: unclear | AD2: Low | AE2: Mihaela Pašek-Virlan — Partner and CEO (since early 2020) (Medium (own-domain snippet; page undated)) https://www.accace.com/about-us/meet-our-key-people/ Alžbeta Košinár — Business Development & Community Lead, Accace Circle (Medium) https://circle.accace.com/ (interview indexed on circle.accace.com) | AG2: 2026-10-08
A3: =RANK(K3,$K$2:$K$21)+COUNTIF($K$2:K3,K3)-1 -> 2 | B3: Eurofast | C3: https://eurofast.eu | D3: Nicosia, Cyprus (group); large Athens operation (Kallithea, Athens phone +30 210 82 57 720 per third-party profile) | E3: TOP-10 · Приоритет 1 | F3: 17 | G3: 24 | H3: 12 | I3: 12 | J3: 11 | K3: =SUM(F3:J3) -> 76 | L3: 76 | M3: =K3-L3 -> 0 | N3: profile_fit: Multi-country SEE/Black Sea advisory firm with recurring accounting/payroll/tax/legal services - very close to Legitimus' target profile. recurring_client_potential: Its clients need ongoing payroll, accounting and compliance; a Moldova entity for a regional client would generate recurring legal/corporate work. Volume of Moldova demand unproven. local_legal_partner_cooperation: Belongs to BKR and PrimeGlobal networks, which suggests it is used to cross-referrals, but its legal work is done in-house and no law-firm partner page was found. moldova_commercial_interest: Moldova is a clear gap between its Bucharest/Targoviste and Kyiv offices, and it keeps expanding (3 new SEE offices). No stated interest in Moldova found. decision_maker_accessibility: Two Managing Directors are named on the company's own domain; a direct email or phone line was not verified. | O3: yes - ACTIVE in 2024-2026 — (1) 'Eurofast-Company-Profile_2026-1.pdf' hosted on eurofast.eu under /wp-content/uploads/2026/05/ (May 2026); (2) own-domain profile: Antonis Gavrielides 'named Managing Director in June 2025'; (3) own-domain press release on new offices in Thessaloniki, Plovdiv and Nis (Irena Damianou quoted as Managing Director; '24 offices in 24 cities across 20 countries'; date not shown in snippet); (4) March 2024 rebrand (new logo + website) reported by PrimeGlobal and BKR; (5) Eurofast International Ltd Tax Advisor job posting (ergodotisi.com) reported dated 31 July 2026; (6) live Tax & Legal Advisor posting in Nis, Serbia (infostud). Direct fetch of eurofast.eu failed (DNS ENOTFOUND in this environment) - not evidence of site being down. [Medium-High] https://eurofast.eu/wp-content/uploads/2026/05/Eurofast-Company-Profile_2026-1.pdf https://eurofast.eu/member/gavrielides-antonis/ https://eurofast.eu/eurofast-expands-regional-presence-with-new-offices-in-southeast-europe/ https://www.primeglobal.net/news/new-brand-identity-eurofast https://bkr.com/cyrpus-member-eurofast-introduces-refreshed-brand-identity/ https://ergodotisi.com/jobs/6999150/Eurofast+International+Ltd/Tax+Advisor https://poslovi.infostud.com/posao/tax-legal-advisor/eurofast-international-doo/727867 | P3: Regional business advisory: payroll & employment / EOR, tax & transfer pricing, accounting & compliance, advisory & corporate (incl. trustee) services, tax & legal, global mobility, citizenship & residency, M&A/corporate finance. In-house local advisers incl. lawyers. | Q3: yes - ~20 countries, 24-25 cities — Meet Eurofast page: presence in over 25 cities; fully-fledged offices Athens, Thessaloniki, Nicosia, Sofia, Plovdiv, Bucharest, Belgrade, Nis, Targoviste, Podgorica, Tirana, Skopje, Zagreb, Ljubljana, Pristina, Banja Luka, Sarajevo, Cairo, Tbilisi, Kyiv, Vilnius, Tallinn, Dubai; associate offices Beirut, Erbil. Press release: 24 offices / 24 cities / 20 countries. [Medium] https://eurofast.eu/meet-eurofast/ https://eurofast.eu/eurofast-expands-regional-presence-with-new-offices-in-southeast-europe/ | R3: not found | S3: n/a | T3: Office list on own domain contains no Moldovan city; nearest offices Bucharest, Targoviste (RO) and Kyiv (UA). Searches 'Eurofast Moldova/Chisinau' returned no Eurofast Moldova service. Whether they serve Moldova via Bucharest/Kyiv or a correspondent: not found. | U3: Medium | V3: https://eurofast.eu/meet-eurofast/ | W3: unclear - network membership only; legal delivered in-house — Member of BKR International and PrimeGlobal (accounting/advisory associations), historically Taxand Cyprus member. Meet Eurofast page describes a 'Dream Team' of local advisors 'comprising lawyers, accountants', i.e. legal work done by own staff. No 'local counsel' / law-firm partner page found. ASSUMPTION: for jurisdictions without an office (e.g. Moldova) they would need an external correspondent. [Medium] https://eurofast.eu/meet-eurofast/ https://www.primeglobal.net/firms/eurofast https://bkr.com/cyrpus-member-eurofast-introduces-refreshed-brand-identity/ | X3: yes — Payroll & Employment, Tax & Transfer Pricing, Accounting & Compliance, Advisory & Corporate Services (rebrand 2024); payroll, accounting, tax, global mobility, EOR, corporate services (expansion release). https://www.primeglobal.net/news/new-brand-identity-eurofast https://eurofast.eu/eurofast-expands-regional-presence-with-new-offices-in-southeast-europe/ | Y3: None found. Positioning is ongoing advisory (payroll, accounting, tax, EOR), not registration packages. | Z3: info@eurofast.eu | AA3: +30 210 82 57 720 (Athens, per career.auth.gr); +357 22 699 000 (Nicosia, per BKR directory per agent 01 - not re-confirmed) | AB3: not verified (eurofast.eu not fetchable) | AC3: unclear | AD3: Low | AE3: Antonis Gavrielides — Managing Director (since June 2025; formerly Group CEO from Nov 2022) (Medium) https://eurofast.eu/member/gavrielides-antonis/ Irena Damianou — Managing Director (Nicosia); formerly Chief Marketing Officer / Board member (Medium) https://eurofast.eu/member/damianou-irena/ ; https://eurofast.eu/eurofast-expands-regional-presence-with-new-offices-in-southeast-europe/ Christodoulos (Chris) Damianou — Non-Executive Chairman (as of Gavrielides CEO appointment, 2022) - current role not re-confirmed (Low) https://eurofast.eu/antonis-gavrielides-appointed-new-eurofast-group-ceo/ | AG3: 2026-10-08
A4: =RANK(K4,$K$2:$K$21)+COUNTIF($K$2:K4,K4)-1 -> 3 | B4: BridgeWest (BridgeWest Legal Network) | C4: https://bridgewest.eu | D4: Unclear: LinkedIn company page lists Nicosia, Cyprus (founded 2008); main contact page lists a Malta address in San Gwann. Not registry-verified. | E4: TOP-10 · Приоритет 1 | F4: 17 | G4: 17 | H4: 19 | I4: 11 | J4: 11 | K4: =SUM(F4:J4) -> 75 | L4: 87 | M4: =K4-L4 -> -12 | N4: profile_fit: Multi-country formation + legal/accounting network delivered by independent local firms - close to Legitimus's target profile; weakened by offshore/shelf focus and thin content. recurring_client_potential: Volume of Moldova referrals unknown; ongoing services exist in some countries but Moldova offer is formation-centric. ASSUMPTION: modest but steady flow of foreign-investor files. local_legal_partner_cooperation: Entire delivery model relies on independent local law firms/affiliates; partner law firms publicly named; 'Join Our Network' section. moldova_commercial_interest: Already sells Moldova (formation, shelf companies, VAT) - demonstrates demand; but slot may be filled by an existing affiliate, so Legitimus would need to replace/complement it. decision_maker_accessibility: Small network; co-founder identifiable via LinkedIn; generic office@ email. Contact-page freshness unclear. | O4: yes - site indexed with many jurisdiction pages; recency only partly verifiable (some country guide pages indexed ~190-270 days old, some contact pages 3,000+ days old). No 2025-2026 dated news/press found. — [Medium] https://bridgewest.eu/ https://bridgewest.eu/about-us/ https://bridgewest.eu/company-formation-kuwait/ https://www.linkedin.com/company/bridgewest-limited | P4: International company formation, accounting/financial, immigration and legal services delivered through independent local affiliates (law firms, consultants, accountants); also shelf companies, EU VAT registration, offshore and licensing (crypto/gaming). | Q4: yes — Own claim: network 'activating in over 70 countries' (LinkedIn: 'over 65 countries'); country pages/divisions for Ireland, Singapore, Germany, Denmark, Portugal, Luxembourg (via Luxstart S.A.), Romania, Georgia, Bosnia, etc. [Medium] https://bridgewest.eu/about-us/ https://bridgewest.eu/about-us-ireland/ https://bridgewest.eu/about-us-luxembourg/ https://www.linkedin.com/company/bridgewest-limited | R4: offered | S4: unclear | T4: Dedicated page: 'team of company registration agents in Moldova' for local/foreign investors, ready-made Moldovan companies and VAT registration. Sitemap lists an 'About Us Moldova' page whose content was not visible; identity of the Moldovan affiliate not found (ASSUMPTION: delivered by an independent Moldovan affiliate, consistent with network model). | U4: Medium | V4: https://bridgewest.eu/company-formation-moldova/ https://bridgewest.eu/website-sitemap/ | W4: yes — Business model built on independent affiliates incl. law firms; 'Partner Law Firms' page names local firms (e.g. Rolegal and E&C in Bucharest 'part of our legal network'); homepage 'Join Our Network' section (terms not visible). Cyprus page profiles a lawyer (Cyprus Bar member since 1980). [Medium] https://bridgewest.eu/ https://www.bridgewest.eu/partner-law-firms https://bridgewest.eu/about-us/ | X4: partial — Accounting, bookkeeping, audit, tax consulting, virtual office (e.g. Luxembourg, Armenia pages); immigration; legal services via affiliates. No Moldova-specific ongoing services found. https://bridgewest.eu/about-us-luxembourg/ https://bridgewest.eu/company-registered-office-armenia/ https://bridgewest.eu/about-us/ | Y4: Moderate: heavy formation/shelf-company/offshore marketing, 'ready-made' companies, tax-minimisation structures; many thin SEO country pages. Some country pages mention accounting/virtual office, so not purely one-off. | Z4: office@bridgewest.eu | AA4: (+35) 699 699 405 on main contact page (ASSUMPTION: Malta mobile +356 9969 9405, prefix printed incompletely); +44 203 287 0408 appears on Bahamas page | AB4: https://bridgewest.eu/contact/ | AC4: unclear | AD4: Medium | AE4: Vlad Cuc — Co-founder and General Director, BridgeWest (per LinkedIn headline) (Low) https://www.linkedin.com/in/vlad-cuc-21152610/ | AG4: 2026-10-08
A5: =RANK(K5,$K$2:$K$21)+COUNTIF($K$2:K5,K5)-1 -> 4 | B5: Healy Consultants Group (part of Hawksford) | C5: https://www.healyconsultants.com | D5: Singapore (16 Raffles Quay, #32-03 Hong Leong Building); Dubai office; parent Hawksford (Jersey) since Sept 2023 | E5: TOP-10 · Приоритет 1 | F5: 17 | G5: 21 | H5: 16 | I5: 12 | J5: 8 | K5: =SUM(F5:J5) -> 74 | L5: 81 | M5: =K5-L5 -> -7 | N5: profile_fit: Global multi-country set-up house with ongoing compliance services and an active Moldova product. recurring_client_potential: Publishes Moldova annual running costs (accounting/tax/audit), implying recurring local work per client. Volume unknown. local_legal_partner_cooperation: Explicitly works with local lawyers in 180+ locations, evidenced by law-firm testimonials; no formal partner programme. moldova_commercial_interest: Actively markets Moldova with detailed pages; existing local provider likely, and page freshness uncertain. decision_maker_accessibility: Founder semi-retired; now inside Hawksford group, current Healy operational leadership not found; only generic email. | O5: yes - live; contact page uses healy@hawksford.com; pages titled 2026 (though search metadata shows Moldova pages ~797 days old) — [Medium] https://www.healyconsultants.com/contact-us/ https://www.hawksford.com/insights-and-guides/hawksford-acquires-healy-consultants | P5: Global business set-up: company registration, corporate bank account opening, immigration, accounting and tax filing, licensing - for SMEs/multinationals expanding abroad. | Q5: yes — Claims set-up in 200+ countries since 2003 and professional relationships with banks, governments, lawyers and accountants in 180+ locations. [Medium] https://www.healyconsultants.com/about-us/ https://www.healyconsultants.com/ | R5: offered | S5: unclear | T5: Dedicated Moldova pages: LLC with 1 director/1 shareholder, US$300 min capital, ~2 weeks, filings with State Registration Chamber via power of attorney; fee page cites avg first-year engagement US$10,145 and annual US$1,475-3,775 (internal inconsistency). No own Moldovan office found. ASSUMPTION: execution via local Moldovan lawyers/agents. | U5: Medium | V5: https://www.healyconsultants.com/moldova-company-registration/ https://www.healyconsultants.com/moldova-company-registration/incorporation-steps/ https://www.healyconsultants.com/moldova-company-registration/fees-timelines/ https://www.healyconsultants.com/moldova-company-registration/setup-llc/ | W5: yes — Site states relationships with lawyers and accountants in 180+ locations; testimonials from local law firms working with Healy (Lebanese law firm since 2014; Baoleki Attorneys, Botswana, since 2018); Malaysia case mentions 'our solicitor in Kuala Lumpur'. No formal partner programme page found. [Medium] https://www.healyconsultants.com/clients/testimonials/ https://www.healyconsultants.com/about-us/ | X5: yes — Annual accounting, tax filing, audit coordination, registered office, immigration; Moldova page cites annual audited financial statements and annual running costs. https://www.healyconsultants.com/moldova-company-registration/ https://www.hawksford.com/insights-and-guides/hawksford-acquires-healy-consultants | Y5: Low-moderate: strong formation focus with fixed engagement fees, but fees bundle bank account, registered office, accounting and tax; annual renewal fees published. | Z5: healy@hawksford.com | AA5: +65 6031 0332 (SG); +971 4266 4470 (Dubai); WhatsApp +65 9123 7743 | AB5: https://www.healyconsultants.com/contact-us/ | AC5: yes | AD5: Medium | AE5: Aidan Healy — Founder / Managing Director (self-profile states semi-retired since 2018, relies on CEOs) (Medium) https://www.healyconsultants.com/about-us/key-personnel/aidan-healy-profile/ Michel van Leeuwen — Group Chief Executive, Hawksford (as of Sept 2023 announcement) (Medium) https://www.hawksford.com/insights-and-guides/hawksford-acquires-healy-consultants | AG5: 2026-10-08
A6: =RANK(K6,$K$2:$K$21)+COUNTIF($K$2:K6,K6)-1 -> 5 | B6: Commitbiz (Commitbiz LLC) | C6: https://www.commitbiz.com | D6: Dubai, UAE (10th floor, Dubai World Trade Center, Sheikh Zayed Road) | E6: TOP-10 · Приоритет 1 | F6: 15 | G6: 19 | H6: 17 | I6: 9 | J6: 10 | K6: =SUM(F6:J6) -> 70 | L6: 83 | M6: =K6-L6 -> -13 | N6: profile_fit: Genuine CSP with formation plus recurring accounting/compliance; core is GCC, not Europe, so Moldova is adjacent rather than central. recurring_client_potential: Large GCC client base (claims 10k-20k clients) incl. CIS/Eastern European founders via Moscow/Bucharest offices; plausible flow of UAE-Moldova structures (DTT exists), but volume of Moldova demand is unproven. local_legal_partner_cooperation: Only company in batch with a published bilateral referral agreement (two-way leads, 20% fee). Not law-firm-specific. moldova_commercial_interest: No Moldova service; Bucharest office and Moscow office suggest regional clientele; UAE-Moldova DTT referenced on site. decision_maker_accessibility: MD named in 2025 press release; general contact channels live; no named partnerships head. | O6: yes - active 2025-2026 — [High] https://www.commitbiz.com/contact-us https://www.prnewswire.com/ae/ar/news-releases/u0645u0643u062Au0628u002Du0063u006Fu006Du006Du0069u0074u0062u0069u007Au002Du0641u064Au002Du062Fu0628u064Au002Du064Au064Eu062Du0635u0644u002D-302530821.html https://aijourn.com/?p=382000 | P6: UAE/GCC business setup (mainland, free zone, offshore), PRO/visa, accounting & bookkeeping, VAT & corporate tax, audit support, entity management/compliance (ESR, CRS, FATCA), IP, commercial contracts. Core market is GCC; European offices are secondary. | Q6: yes — Formation/PRO pages for UAE, Qatar, Bahrain, Saudi Arabia, Oman; offices listed in Dubai, Abu Dhabi, Sharjah, Sanabis (Bahrain), Doha, Barka (Oman), London, Moscow, Naples, Bucharest. [Medium] https://www.commitbiz.com/contact-us https://www.commitbiz.com/sa/pro-services-in-saudi-arabia | R6: not found | S6: n/a | T6: Moldova appears only in the UAE double-tax-treaty list on the tax residency certificate page. No Moldova formation page found. Romania (Bucharest) office address exists on contact page, but Romanian office phone shown with +971 code - office may be a representative/virtual presence (ASSUMPTION). | U6: Medium | V6: https://www.commitbiz.com/tax-residency-certificate-uae https://www.commitbiz.com/contact-us | W6: yes - formal two-way referral agreement published — Published REFERRAL AGREEMENT: either party may refer leads via referral form; 7 days to accept/decline; referral fee 20% of professional fee per conversion (or referrer adds a margin); 30-day termination; 1-year non-solicit; UAE law, Dubai courts. Not law-firm-specific, but a ready bilateral B2B model. Blog mentions a business unit head with corporate lawyer background; no named external law-firm network found. [High] https://www.commitbiz.com/refer-and-earn-terms-conditions | X6: yes — Accounting & bookkeeping, payroll, VAT returns, corporate tax compliance, audit support, entity management (ESR/CRS/FATCA/governance), PRO services. https://www.commitbiz.com/accounting-bookkeeping-services-in-dubai-uae https://www.commitbiz.com/vat-in-uae https://www.commitbiz.com/business-management-services-uae | Y6: Moderate: package pricing ('from AED 12,345'), cost pages for 2026, claims of 10,000-20,000 businesses incorporated; but bundled with ongoing accounting/VAT/PRO. Homepage disclaimer reportedly names a separate entity 'RC Migration' - template artefact or affiliate; needs check. | Z6: info@commitbiz.com (from agent 01; not re-confirmed in this check) | AA6: +971 4 386 7444 (shown in contact page title); +971 4 871 4159 not re-confirmed | AB6: https://www.commitbiz.com/contact-us | AC6: yes | AD6: Medium | AE6: Manu Thomas V — Managing Director, Commitbiz LLC (Medium) https://aijourn.com/?p=382000 (PRNewswire release, 14 Aug 2025) | AG6: 2026-10-08
A7: =RANK(K7,$K$2:$K$21)+COUNTIF($K$2:K7,K7)-1 -> 6 | B7: The Sovereign Group | C7: https://www.sovereigngroup.com | D7: Gibraltar (Sovereign Place, 117 Main Street) - founded 1987 | E7: TOP-10 · Приоритет 2 | F7: 17 | G7: 20 | H7: 14 | I7: 6 | J7: 12 | K7: =SUM(F7:J7) -> 69 | L7: 77 | M7: =K7-L7 -> -8 | N7: profile_fit: Large, established independent CSP with exactly the long-term corporate/trust admin profile sought; offshore/IFC-heavy rather than CEE. recurring_client_potential: Scale (20k structures, 20+ offices) and HNW/corporate client base can generate recurring needs, but no evidence of existing Moldova demand. local_legal_partner_cooperation: Explicitly serves and builds referral networks with lawyers/accountants and offers white-label to intermediaries; no formal introducer terms published. moldova_commercial_interest: No CEE/Moldova footprint visible; Cyprus and Malta offices are the nearest relevant hubs for CIS-origin structures (ASSUMPTION). decision_maker_accessibility: Named CEO, Group Sales Director and regional BD heads on own site; team pages undated. | O7: yes - active — [High] https://www.sovereigngroup.com/offices/ https://www.sovereigngroup.com/events/sovereign-at-going-global-live-2025/ https://www.sovereigngroup.com/news/sovereign-group-acquires-pro-partner-group-to-further-expand-its-gcc-footprint/ | P7: Independent corporate & trust services provider: company formation & management, back-office, tax and regulatory compliance, cross-border restructuring, trusts, pensions, residency/citizenship planning, family office. | Q7: yes - 20+ jurisdictions — Offices page lists ~23 entries (Abu Dhabi, Bahrain, Cyprus, Dubai, Gibraltar, Guernsey, Hong Kong, Isle of Man, Malta, Mauritius, Oman, Portugal, Qatar, Saudi Arabia, Singapore, Cape Town, Switzerland, London, Chester); locations page adds Bahamas, Turks & Caicos. Claims 20,000 structures since 1987, 400+ staff, 30+ licences. [High] https://www.sovereigngroup.com/offices/ https://www.sovereigngroup.com/locations/ https://www.sovereigngroup.com/our-services/corporate-services/ | R7: not found | S7: n/a | T7: No Moldova or Romania pages/offices in domain-restricted searches; no CEE office. | U7: Medium | V7: https://www.sovereigngroup.com/locations/ | W7: yes - works with and for professional intermediaries — Offices serve 'professional intermediaries'; Isle of Man and Dubai offer white-label services so professional firms deliver structures under their own brand; BD roles focus on relationships with accountants, legal and tax advisors; jobs ad mentions building referral networks with law and accounting firms. No formal introducer programme page or published terms. [Medium] https://www.sovereigngroup.com/isle-man/ https://www.sovereigngroup.com/dubai/ https://www.sovereigngroup.com/staff/herman-redelinghuys/ https://www.sovereigngroup.com/jobs/trust-and-corporate-services-consultant/ | X7: yes — Company management, back-office, tax & regulatory compliance, trusts, pensions, family office. https://www.sovereigngroup.com/our-services/corporate-services/ | Y7: Low. Positioned on ongoing administration, trusts, pensions, compliance. No '24h company' style selling seen. | Z7: info@SovereignGroup.com; gib@SovereignGroup.com (from agent 01, not re-confirmed) | AA7: +350 200 76173 (Gibraltar, from agent 01, not re-confirmed) | AB7: https://www.sovereigngroup.com/contact-us/ | AC7: yes | AD7: Medium | AE7: Gerry Kelly — Group Chief Executive Officer (Medium) https://www.sovereigngroup.com/staff/gerry-kelly/ Howard Bilton — Group Chairman and founder (Medium) https://www.sovereigngroup.com/staff/howard-bilton/ Nicholas Cully — Group Sales Director (Medium) https://www.sovereigngroup.com/sovereign-stories/nicholas-cully-group-sales-director/ Sebastien Philipona — Head of Business Development, Malta & Cyprus (Medium) https://www.sovereigngroup.com/staff/sebastien-philipona/ Ejaz Niazi — Head of Business Development, Sovereign Trust (Gibraltar) Ltd (Medium) https://www.sovereigngroup.com/staff/ejaz-niazi/ | AG7: 2026-10-08
A8: =RANK(K8,$K$2:$K$21)+COUNTIF($K$2:K8,K8)-1 -> 7 | B8: TMF Group | C8: https://www.tmf-group.com | D8: Amsterdam, Netherlands | E8: TOP-10 · Приоритет 2 | F8: 17 | G8: 26 | H8: 8 | I8: 9 | J8: 7 | K8: =SUM(F8:J8) -> 67 | L8: 68 | M8: =K8-L8 -> -1 | N8: profile_fit: Global entity-management/corporate secretarial leader - ideal client type, but enterprise-scale and own-entity model. recurring_client_potential: Multinational clients with recurring compliance needs; any Moldova entity for them would generate ongoing legal work. local_legal_partner_cooperation: Operates own entities; no public local-partner programme; only LAWorld distribution-type tie found. moldova_commercial_interest: Genuine gap next to Romania/Ukraine, but no sign TMF plans Moldova coverage; ASSUMPTION: ad-hoc client requests exist. decision_maker_accessibility: Regional heads named in press, but large corporate; access likely only via Romania office/procurement. | O8: yes - very active; Nordgain acquisition effective 3 Oct 2025, Estonia office Mar 2026, Vilnius client event May 2026 — [High] https://www.tmf-group.com/en/news-insights/press-releases/tmf-group-acquires-nordgain/ https://www.baltictimes.com/tmf_group_expands_into_estonia_following_its_acquisition_of_nordgain https://www.tmf-group.com/en/news-insights/events-webinars/tmf-group-nordgain-client-reception-celebrating-new-chapter-baltics/ | P8: Enterprise corporate secretarial, entity management, accounting & tax, HR/payroll, fund/capital markets administration | Q8: yes — 125+ offices in 87 jurisdictions (own locations and regulatory status pages). [High] https://www.tmf-group.com/en/locations/ https://www.tmf-group.com/en/legal/regulatory-status | R8: not found | S8: n/a | T8: No Moldova page or office in results; nearest office Bucharest, Romania (America House, Country Manager Gabriel Sincu). | U8: Medium | V8: https://www.tmf-group.com/en/locations/emea/romania https://mediafax.ro/comunicate/tmf-group-a-leading-provider-of-compliance-and-administrative-services-22555939/amp | W8: limited evidence — 2025 partnership agreement with LAWorld (network of independent law firms) making TMF available to LAWorld members and clients - TMF sells to law-firm networks rather than sourcing local counsel; no partner programme for non-office jurisdictions found. [Low] WebSearch summary 'TMF Group partner network' 2026-10-08 (LAWorld announcement; URL not shown) https://www.tmf-group.com/en/locations/ | X8: yes — Accounting, legal/secretarial, tax, payroll, HR in Romania and group-wide. https://www.tmf-group.com/en/locations/emea/romania | Y8: None - recurring entity management model. | Z8: not found | AA8: +31 20 575 5600 (third-party only) | AB8: not verified | AC8: unclear | AD8: Low | AE8: Gabriel Sincu — Country Manager Romania (Nov 2024 press release) (Medium (may be outdated)) https://mediafax.ro/comunicate/tmf-group-a-leading-provider-of-compliance-and-administrative-services-22555939/amp Jan Willem van Drimmelen — Head of Europe (Medium) https://www.tmf-group.com/en/news-insights/press-releases/tmf-group-acquires-nordgain/ Agnė Jasinskaitė — Country Head of the Baltics (Medium) https://www.baltictimes.com/tmf_group_expands_into_estonia_following_its_acquisition_of_nordgain | AG8: 2026-10-08
A9: =RANK(K9,$K$2:$K$21)+COUNTIF($K$2:K9,K9)-1 -> 8 | B9: GSL (GSL Law & Consulting group) | C9: https://gsl.org | D9: Moscow, Russia (head office; Russian-language site, Moscow contact page, +7 phone); also registered entities e.g. GSL Law & Consulting (Hong Kong) Ltd; London office since 2002 | E9: Отложено: требуется комплаенс-проверка | F9: 13 | G9: 18 | H9: 12 | I9: 13 | J9: 9 | K9: =SUM(F9:J9) -> 65 | L9: 68 | M9: =K9-L9 -> -3 | N9: profile_fit: Multi-jurisdiction formation plus tax/legal; but it is a competing law firm with heavy offshore/package orientation. recurring_client_potential: Already sells Moldova packages with annual compliance fees, so each sale implies recurring local work; client base is Russia-origin, which raises compliance cost. local_legal_partner_cooperation: States it works through trusted foreign partners; no program; likely already has a Moldovan agent (unknown). moldova_commercial_interest: Explicit Moldova formation and tax pages with pricing - clear existing commercial interest. decision_maker_accessibility: Managing partner named on own site; Moscow-centric contacts; office staff listings partly outdated. | O9: yes - active 2025-2026 — [High] https://gsl.org/ru/press-center/corporate-news/gsl-law-consulting-v-rejtinge-luchshih-yuridicheskih-firm-i-yuristov-private-wealth-2026-id-kommersant/ https://gsl.org/ru/press-center/corporate-news/gsl-law-consulting-v-rejtinge-wealth-navigator-2026/ | P9: Russian-origin law, tax, audit and consulting group: offshore/onshore company registration (claims 20,000+ companies in 81 countries), international tax structuring, bank account introductions, foreign-trade (VED) support, relocation, Russian law practice. It is itself a law firm (Russian 'advokat' partners), not a pure CSP. | Q9: yes — Offices claimed: London, Moscow, Limassol/Nicosia, Hong Kong, Budapest, Bali, Phuket, Istanbul, Dubai, Riga, Oradea (Romania), Tortola, Mahe, Andorra, California; registers in 70-80+ countries (self-claim). [Medium] https://gsl.org/en/offshore/ https://gsl.org/en/contacts/ https://www.gsl.org/ru/ | R9: offered | S9: unclear | T9: Moldova page: incorporation or shelf company, registered office, apostilled docs, secretarial, bank pre-approval; EUR 2,000 incl. state fees; compliance fee USD 385; 1-3 workdays LLC. Also Moldova tax page. No Moldovan office listed -> almost certainly delivered via a local partner (ASSUMPTION). | U9: High | V9: https://gsl.org/en/offshore/offshore-zones/eastern-europe/moldova/ https://gsl.org/ru/taxes/moldova/ | W9: yes (general) — States 'many trusted partners in different countries' and 'direct representation in several popular jurisdictions'; historically ran international conferences (2003-2006) connecting Russian clients with foreign banks, trust companies and law firms. No partner programme page. [Medium] https://gsl.org/en/offshore/ https://gsl.org/en/international/2003-1/ | X9: yes — Annual compliance/administration fees, secretarial, audit (GSL Audit), tax reporting, legal advice, bank account support. https://gsl.org/en/offshore/offshore-zones/eastern-europe/moldova/ https://gsl.org/en/hello/ | Y9: Significant: fixed-price jurisdiction packages, shelf companies, 'offshore' framing (incl. Moldova labelled offshore), price comparison tables. Offset by tax/accounting/legal practices. | Z9: gsl@gsl.org | AA9: +7 495 234 3833 (Moscow); +44 (0)20 7822 8593 (London) | AB9: https://gsl.org/en/contacts/ | AC9: unclear | AD9: Medium | AE9: Alexander Alekseev — Managing Partner, GSL Law & Consulting (Medium) https://gsl.org/en/users/alexander-alekseev/ ; https://gsl.org/en/hello/ Aniko Sebok — Head of UK (London) office (Medium) https://gsl.org/en/contacts/ Maksim Gladyr — Head of Foreign Economic Activity (VED) department (Medium) https://gsl.org/ru/users/maksim-gladyr/ | AG9: 2026-10-08
A10: =RANK(K10,$K$2:$K$21)+COUNTIF($K$2:K10,K10)-1 -> 9 | B10: Uniwide | C10: https://www.uniwide.com | D10: Dubai, UAE (group main office since 2023); EU office Riga, Latvia | E10: TOP-10 · Приоритет 2 | F10: 12 | G10: 16 | H10: 14 | I10: 8 | J10: 10 | K10: =SUM(F10:J10) -> 60 | L10: 81 | M10: =K10-L10 -> -21 | N10: profile_fit: Multi-jurisdiction formation provider with Baltic/Russian-speaking base, but offshore-heavy and formation-led. recurring_client_potential: Some recurring compliance/accounting, but much of the flow is one-off formation and bank introductions. local_legal_partner_cooperation: Reported partner programme with referral/subcontractor models and reliance on local agents; not re-verified this run. moldova_commercial_interest: No Moldova offer found; ASSUMPTION: Russian-speaking/Baltic client base could generate Moldova demand. decision_maker_accessibility: Named Latvia head on own domain; contact page exists; no general email found. | O10: yes - own-domain pages indexed (about, team, Seychelles agent article, UAE recognition news) — [Medium] https://www.uniwide.com/about/ https://www.uniwide.com/about/our-team/ https://www.uniwide.com/uniwide-advisors-recognised-as-one-of-the-most-promising-company-registration-consultants-in-the-uae/ | P10: International company formation (incl. offshore), bank account support, registered office/agent, post-incorporation compliance, accounting | Q10: yes — Offices Riga (2014), Seychelles (2015, licensed registered agent 2016), London (2019), Dubai (2023); 30+ jurisdictions per directory and agent 01 snippets. [Medium] https://www.uniwide.com/about/ https://www.uniwide.com/which-is-the-best-registered-agent-for-an-offshore-company-in-seychelles/ https://directory.partner.io/uniwide-biz | R10: not found | S10: n/a | T10: No uniwide.com page mentioning Moldova surfaced in searches. | U10: Low | V10: WebSearch 'Uniwide company formation Moldova' 2026-10-08 (no uniwide.com result) | W10: reported (partner programme for law firms) - not re-confirmed this run — Agent 01 cites uniwide.com/partner-programme (referral and subcontractor models, aimed at law firms, banks, PSPs, tax advisers) and 'partnerships with local registration agents'. Re-check searches returned no uniwide.com partner page. [Low] https://www.uniwide.com/partner-programme/ (per agent 01; not re-surfaced) https://www.uniwide.com/about/ | X10: partial — Registered office/agent, post-incorporation compliance and accounting listed (directory description). https://directory.partner.io/uniwide-biz | Y10: Strong formation/offshore orientation (Seychelles, offshore centres, bank account opening) - partly one-off registration selling; compliance/accounting offered as add-ons. | Z10: not found | AA10: +371 6611 8787 (Riga); +44 (0)20 4501 0600 (London) - per agent 01, not re-checked | AB10: https://www.uniwide.com/contact/ | AC10: unclear | AD10: Low | AE10: Jurgis Naunikas — Head of Office, Latvia (Medium) https://www.uniwide.com/about/our-team/ Alexei Kariakin — General Manager, Uniwide Advisors (per Siliconindia interview, search summary) (Low) Siliconindia interview (URL not shown in snippet); see https://www.uniwide.com/uniwide-advisors-recognised-as-one-of-the-most-promising-company-registration-consultants-in-the-uae/ | AG10: 2026-10-08
A11: =RANK(K11,$K$2:$K$21)+COUNTIF($K$2:K11,K11)-1 -> 10 | B11: Vistra (incl. Tricor; acquired Biz Latin Hub) | C11: https://www.vistra.com | D11: Hong Kong (19/F, Lee Garden One, 33 Hysan Avenue, Causeway Bay) | E11: TOP-10 · Приоритет 2 | F11: 13 | G11: 24 | H11: 8 | I11: 9 | J11: 5 | K11: =SUM(F11:J11) -> 59 | L11: 68 | M11: =K11-L11 -> -9 | N11: profile_fit: Top-tier recurring corporate services provider, but enterprise scale and own-office model limit fit with a small Moldovan law office. recurring_client_potential: If engaged, clients would need ongoing entity management in Moldova (secretarial, compliance, payroll). ASSUMPTION: low Moldova volume; potential only if Vistra needs a Moldova provider. local_legal_partner_cooperation: No public evidence of law-firm partner network; 170+ country claim suggests third-party providers but unverified. moldova_commercial_interest: Moldova gap next to Romania office; client demand for Moldova not evidenced. decision_maker_accessibility: Large group; only C-level/regional names found, relevant procurement/partnerships contact not found. | O11: yes - very active: CEO appointment (Kim Jenkins, July 2025), Chief AI & Digital Officer (Apr 2026), EVP Americas (June 2026), G-P (Mar 2026) and Oyster (Apr 2026) partnerships, Vistra Latam launch (June 2026) — [High] https://www.vistra.com/insights/vistra-appoints-kim-jenkins-group-chief-executive-officer https://www.vistra.com/insights/vistra-launches-partnership-g-p-bridge-eor-and-entity-based-expansion-and-simplify https://cfotech.news/story/vistra-launches-latam-unit-after-biz-latin-hub-deal | P11: Global corporate services (entity management, company secretarial, accounting, payroll, international expansion), fund administration and private client services. | Q11: yes — 50+ markets, 9,000+ colleagues; claims coverage of 170+ countries via Vistra Global Solutions; CEE offices incl. Poland and Romania (Bucharest, Vistra Professional Services SRL). [High] https://careers.vistra.com/ https://www.vistra.com/vgs https://www.vistra.com/locations/emea/romania https://www.vistra.com/locations/emea/poland | R11: not found | S11: n/a | T11: Only Moldova mention on vistra.com is in an apostille-country list. No Moldova office/service page found. (Name coincidence: Kristopher Moldovan is CFO of Vistra Corp - unrelated US energy company.) | U11: Medium | V11: https://www.vistra.com/speciality-services/legalisation/apostille-faqs | W11: unclear — Vistra states it is not a law firm and has no notaries/solicitors on staff; claims 170+ country coverage (ASSUMPTION: non-office countries served via third-party providers, possibly law firms). Public partnerships found are EOR (G-P, Oyster), not law firms. Pre-acquisition affiliate arrangement with Biz Latin Hub. [Low] https://www.vistra.com/speciality-services/legalisation/apostille-faqs https://www.vistra.com/vgs https://www.vistra.com/insights/vistra-and-oyster-partner-expand-global-workforce-solutions | X11: yes — Entity management, company secretarial, accounting/compliance, payroll/HR, nominee directors (e.g., Romania). https://www.vistra.com/locations/emea/romania https://www.vistra.com/corporate/entity-management-solution | Y11: None significant - enterprise recurring-services model. | Z11: not found | AA11: +852 2521 3661 (HQ); Romania +40 21 311 8815 | AB11: https://www.vistra.com/contact-form | AC11: yes | AD11: High | AE11: Kim Jenkins — Group Chief Executive Officer (from July 2025) (High) https://www.vistra.com/insights/vistra-appoints-kim-jenkins-group-chief-executive-officer Steven van Tuijl — Regional Managing Director, Continental Europe (appointed June 2021 - may be outdated) (Medium) https://vistra.com/insights/vistra-appoints-steven-van-tuijl-regional-managing-director-continental-europe | AG11: 2026-10-08
A12: =RANK(K12,$K$2:$K$21)+COUNTIF($K$2:K12,K12)-1 -> 11 | B12: Virtuzone | C12: https://virtuzone.com | D12: Dubai, UAE (owned by Ascentium, Singapore, since Jan 2025) | E12: TOP-10 · Приоритет 2 | F12: 13 | G12: 20 | H12: 11 | I12: 7 | J12: 8 | K12: =SUM(F12:J12) -> 59 | L12: 82 | M12: =K12-L12 -> -23 | N12: profile_fit: Large corporate service provider with recurring services, but its core is UAE inbound formation, not CEE coverage. recurring_client_potential: Big client base (75-80k entrepreneurs claimed). Some are CIS/Moldovan founders who may need home-country legal work. The flow towards Moldova is speculative. local_legal_partner_cooperation: It has a track record of a JV with a law firm (Seven Pillars), but the current public scheme is a generic paid-referral programme. moldova_commercial_interest: No Moldova service; the CIS JV status is unknown. Ascentium is now entering Europe (PL/DE/IT), which is a weak, indirect signal. decision_maker_accessibility: Senior names are known from press, but it is a large corporate under new PE-backed ownership, with no partnerships head identified. | O12: yes - active — Acquisition by Ascentium reported 22 Jan 2025 (Enterprise AM, Gulf Business); referral platform live; agent 01 found 2025 regulatory content on site. [High] https://enterpriseam.com/uae/2025/01/22/singapores-ascentium-is-the-new-owner-of-dubai-based-virtuzone/ https://gulfbusiness.com/en/2025/dubai/virtuzone-has-been-acquired-by-singapore-based-ascentium/ https://referral.virtuzone.com/ | P12: UAE company formation (mainland/free zone), corporate services, tax & accounting, Golden Visa, banking, compliance & legal, trademarks; sister brands Taxready, Next Generation Equity, Maktabi | Q12: UAE-centred; parent Ascentium in 27 markets (after April 2026 Dezan Shira acquisition, incl. Poland, Germany, Italy) — Virtuzone's offshore page lists 5 jurisdictions (per agent 01); Ascentium acquired Dezan Shira in April 2026 -> 27 markets; earlier 23 markets/45 cities (Dec 2025); also acquired Clara (ADGM, Feb 2026), ZICO (Aug 2025). [Medium] https://www.china-briefing.com/news/ascentium-acquires-dezan-shira-associates-expanding-its-footprint-to-27-markets-and-strengthening-corporate-services-capabilities/ https://www.aap.com.au/aapreleases/cision20251210ae41303 | R12: not found | S12: n/a | T12: No Moldova formation service found. A CIS-focused JV (Virtuzone CIS with Seven Pillars Law, AIFC Astana) covered CIS/Central Asia c.2020; its current status was not found. | U12: Medium | V12: https://virtuzone.com/press-release/virtuzone-and-seven-pillars-law-create-joint-venture-virtuzone-cis/ | W12: yes (historic) - JV with law firm Seven Pillars Law — Virtuzone CIS JV with Seven Pillars (Central Asian law firm founded by Mark Beer) for formation + legal across CIS/Central Asia; chairman Neil Petch quoted on need for local partners. Public referral platform pays a fixed fee per referred client (AED 3,000 setup / AED 1,500 corporate services, 'estimates may vary') - this is inbound referral to UAE, not a law-firm partnership. [Medium] https://virtuzone.com/press-release/virtuzone-and-seven-pillars-law-create-joint-venture-virtuzone-cis/ https://referral.virtuzone.com/ | X12: yes — Tax and accounting, compliance and legal services, bank account opening, IT & mail management, Golden Visa listed on referral platform; Taxready.ae sister brand. https://referral.virtuzone.com/ | Y12: Strong formation/package orientation (UAE setup), but complemented by tax, accounting, compliance and visa renewals. | Z12: info@virtuzone.com | AA12: +971 4 457 8200 | AB12: https://virtuzone.com/contactus | AC12: unclear | AD12: Medium | AE12: George Hojeige — CEO / Group CEO, Virtuzone (as quoted in Jan 2025 acquisition coverage) (Medium) https://gulfbusiness.com/en/2025/dubai/virtuzone-has-been-acquired-by-singapore-based-ascentium/ Neil Petch — Co-founder and Chairman, Virtuzone (Jan 2025) (Medium) https://mena.entrepreneur.com/finance/virtuzone-taken-over-by-singapores-ascentium/485837 Lennard Yong — CEO, Ascentium (parent) (Medium) https://mena.entrepreneur.com/finance/virtuzone-taken-over-by-singapores-ascentium/485837 Paul Bryson — Managing Director (appointed June 2023; current status not confirmed) (Low) https://gulfnews.com/business/corporate-news/virtuzone-names-paul-bryson-as-managing-director-as-part-of-growth-push-1.1687348960666 | AG12: 2026-10-08
A13: =RANK(K13,$K$2:$K$21)+COUNTIF($K$2:K13,K13)-1 -> 12 | B13: Riz & Mona Consultancy | C13: https://www.rizmona.com | D13: Business Bay, Dubai, UAE | E13: Резерв | F13: 10 | G13: 13 | H13: 11 | I13: 6 | J13: 12 | K13: =SUM(F13:J13) -> 52 | L13: 65 | M13: =K13-L13 -> -13 | N13: profile_fit: A small UAE-only setup consultancy with a mainly one-off service mix; it is international only through associates. recurring_client_potential: Some recurring accounting/VAT work, but the flow of clients towards Moldova is unproven. local_legal_partner_cooperation: It explicitly works through associate firms abroad, so adding a Moldova associate is conceivable. moldova_commercial_interest: It only wrote about the UAE-Moldova visa deal; no service or demand signal. decision_maker_accessibility: A founder-led firm with the CEO named in its own brochure; direct contacts are published. | O13: yes - active — Own domain has an Aug 2025 news item on UAE-Moldova visa-free travel (per agent 01) and a media page listing a 2025 'IBGME acquisition' and a KSA expansion; 2024 ProPakistani article. [Medium] https://www.rizmona.com/media/ https://www.rizmona.com/news/uae-moldova-sign-mutual-visa-free-travel-agreement-in-abu-dhabi/ https://propakistani.pk/2024/09/10/how-businesses-can-save-on-high-taxes-this-company-is-helping-pakistanis-set-up-their-business-in-dubai/amp/ | P13: Dubai business setup: company registration, licences, visas, bank accounts, PRO, trademark/product registration, accounting/bookkeeping, VAT and corporate tax compliance | Q13: limited - UAE plus associate-firm network (SG, MY, MU, KSA named) — Who We Are page: services worldwide through a network of associate firms. [Medium] https://www.rizmona.com/who-we-are/ | R13: not found | S13: n/a | T13: Only a visa-free news item mentions Moldova. | U13: Medium | V13: https://www.rizmona.com/news/uae-moldova-sign-mutual-visa-free-travel-agreement-in-abu-dhabi/ | W13: unclear — 'Network of associate firms' abroad, type not specified; no law-firm partner page found. [Low] https://www.rizmona.com/who-we-are/ | X13: partial — Accounting/bookkeeping, VAT and corporate tax compliance and post-licence support are claimed on its own site. https://www.rizmona.com/who-we-are/ https://rizmona.com/offers/business-setup-consultants | Y13: Strong: setup-package marketing ('offers' landing pages), visa/licence focus; many clients are one-time setups. | Z13: info@rizmona.com | AA13: +971 4 558 6339; WhatsApp +971 54 582 1012 | AB13: https://www.rizmona.com/contact-us/ | AC13: unclear | AD13: Medium | AE13: Rizwan Chaudhary — CEO & Founder (co-founded with wife Mona) (Medium) https://www.rizmona.com/assets/docs/rizmona.pdf | AG13: 2026-10-08
A14: =RANK(K14,$K$2:$K$21)+COUNTIF($K$2:K14,K14)-1 -> 13 | B14: Creation Business Consultants | C14: https://www.creationbc.com | D14: Dubai, UAE (offices DIFC, ADGM licence, Riyadh, Hong Kong, Melbourne) | E14: Исключено | F14: 11 | G14: 15 | H14: 5 | I14: 3 | J14: 11 | K14: =SUM(F14:J14) -> 45 | L14: 52 | M14: =K14-L14 -> -7 | N14: profile_fit: A solid corporate-services firm, but GCC/Asia-focused with no European footprint. recurring_client_potential: Recurring CSP/tax work exists, but it is inside the GCC; little flow towards Moldova. local_legal_partner_cooperation: No evidence of cooperation with foreign law firms. moldova_commercial_interest: No signal at all. decision_maker_accessibility: Founder-MD publicly named; a mid-size firm. | O14: yes - active — ADGM CSP licence (Gulf News / Zawya); 2025 DIFC expansion release; 2024 tax structuring award; 2026 Monash alumni profile of founder. [Medium] https://gulfnews.com/business/corporate-news/creation-business-consultants-expands-uae-corporate-service-capabilities-with-adgm-licence-1.500682234 https://www.creationbc.com/news/creation-bc-wins-best-corporate-tax-structuring-experts-2024-middle-east-award/ https://www.monash.edu/business/alumni/alumni-community/alumni-stories/scott-cairns | P14: GCC market entry, company formation, restructuring, tax planning/corporate tax, accounting, corporate services, ADGM/DIFC CSP | Q14: yes - GCC + offshore + HK — Locations page 'over 10 countries'; GCC, Egypt, HK, BVI, Cayman etc. [Medium] https://www.creationbc.com/locations/ | R14: not found | S14: n/a | T14: No Moldova or CEE coverage found. | U14: Medium | V14: https://www.creationbc.com/locations/ | W14: not found — No law-firm partner/local counsel programme found. [Low] | X14: yes — ADGM CSP: registered office and ongoing filings; corporate tax filing; accounting. https://gulfnews.com/business/corporate-news/creation-business-consultants-expands-uae-corporate-service-capabilities-with-adgm-licence-1.500682234 https://uae-corporate-tax.creationbc.com/ | Y14: Moderate: formation-led, but restructuring/tax/CSP services are ongoing. | Z14: info@creationbc.com | AA14: +971 4 878 6240; +966 11 434 3300 | AB14: https://www.creationbc.com/contact-us/ | AC14: unclear | AD14: Medium | AE14: Scott Cairns — Founder & Managing Director (Medium) https://www.monash.edu/business/alumni/alumni-community/alumni-stories/scott-cairns | AF14: No clear mutual model: GCC/Asia-only focus, no CEE or law-firm cooperation signals. | AG14: 2026-10-08
A15: =RANK(K15,$K$2:$K$21)+COUNTIF($K$2:K15,K15)-1 -> 14 | B15: Tetra Consultants | C15: https://www.tetraconsultants.com | D15: Singapore (67 Ubi Crescent, per agent 01) | E15: Резерв | F15: 10 | G15: 13 | H15: 6 | I15: 6 | J15: 4 | K15: =SUM(F15:J15) -> 39 | L15: 61 | M15: =K15-L15 -> -22 | N15: profile_fit: Global formation/licensing shop, Asia-centred; corporate services exist but are formation-led. recurring_client_potential: Some recurring accounting/compliance, mostly in Singapore; foreign formations look largely one-off. local_legal_partner_cooperation: No partner programme found; reliance on local agents is only assumed. moldova_commercial_interest: No Moldova or nearby (RO/UA) pages; Georgia/Latvia presence shows some Eastern Europe interest. decision_maker_accessibility: No named decision makers found; generic enquiry email only. | O15: yes - active indexed pages (jurisdictions, licences, blog, Georgia case study) — [Medium] https://www.tetraconsultants.com/jurisdictions/register-company-in-singapore/ https://www.tetraconsultants.com/jurisdictions/register-company-in-georgia/case-study | P15: Company registration worldwide, financial/gaming licences (Labuan, Isle of Man, EMI Malaysia), bank account opening, nominee services, accounting & tax | Q15: yes — Register-company pages for Singapore, Georgia, Latvia, Cayman, USA, Canada, Bermuda, Dominica; licence pages Labuan/Isle of Man/Malaysia. [Medium] https://www.tetraconsultants.com/video/register-company-in-latvia/ https://www.tetraconsultants.com/jurisdictions/register-company-in-georgia/case-study https://www.tetraconsultants.com/video/isle-of-man-gaming-license/ | R15: not found | S15: n/a | T15: No tetraconsultants.com Moldova/Romania/Ukraine pages surfaced. | U15: Low | V15: WebSearch site:tetraconsultants.com 2026-10-08 | W15: not found — No partner/referral page found. Georgia case study mentions offering 'legal advisory services' (delivery model unclear). ASSUMPTION: smaller jurisdictions served via local agents. [Low] https://www.tetraconsultants.com/jurisdictions/register-company-in-georgia/case-study | X15: partial — Bookkeeping, tax compliance, Singapore compliance officer, ongoing tax/accounting/legal advisory (Georgia case). https://www.tetraconsultants.com/jurisdictions/register-company-in-singapore/company-incorporation/ https://www.tetraconsultants.com/jurisdictions/register-company-in-georgia/case-study | Y15: Strong - formation/licence packages, nominee directors, 'reply within 24 hours' free consultation, offshore set-ups. | Z15: enquiry@tetraconsultants.com | AA15: not found | AB15: not verified | AC15: yes | AD15: Medium | AE15: not found | AG15: 2026-10-08
A16: =RANK(K16,$K$2:$K$21)+COUNTIF($K$2:K16,K16)-1 -> 15 | B16: InCorp Global (rebranding to Ascentium) | C16: https://www.incorp.asia | D16: Singapore (36 Robinson Road, #20-01 City House); part of Ascentium group (Singapore) | E16: Исключено | F16: 8 | G16: 10 | H16: 6 | I16: 4 | J16: 7 | K16: =SUM(F16:J16) -> 35 | L16: 46 | M16: =K16-L16 -> -11 | N16: profile_fit: Recurring corporate services provider but APAC-only; not a multi-country formation seller into Europe. recurring_client_potential: Recurring model, but Moldova-bound flow from APAC clients would be rare (ASSUMPTION). local_legal_partner_cooperation: Partners are chambers/accounting networks; no law-firm cooperation evidence. moldova_commercial_interest: No Moldova presence or demand signal. decision_maker_accessibility: Group and country CEOs named, but large group mid-rebrand; no partnerships contact. | O16: yes - active; country entities rebranding to Ascentium through 2026 (Philippines Jul 2026, India Sep 2026, Singapore Oct 2026) — [High] https://www.uniindia.com/prnewswire/incorp-india-completes-rebrand-to-ascentium-aligning-domestic-growth-with-global-strategy-302891233/195346 https://macaubusiness.com/incorp-philippines-rebrands-to-ascentium-philippines-reinforcing-commitment-to-a-growing-market/ https://www.thailand-business-news.com/?p=332216 | P16: APAC corporate services: incorporation, corporate secretarial, accounting/tax, payroll, immigration. | Q16: yes (APAC) — 9 APAC markets. Parent Ascentium: 3,000+ professionals, 27 markets, incl. Harneys Fiduciary (BVI, Cayman, Cyprus, HK, Singapore, UK), Virtuzone (UAE), Dezan Shira, MGI Dobbyn Carafa. [Medium] https://www.incorp.asia/about/ https://www.cekindo.com/blog/incorp-is-becoming-ascentium https://kyodonewsprwire.jp/release/202504097131 | R16: not found | S16: n/a | T16: No Moldova pages on incorp.asia; 'Ascentium Moldova' search returned nothing relevant. | U16: Medium | V16: https://www.incorp.asia/about/ | W16: unclear — Partners page lists chambers and networks (Dutch Chambers, Ebury, PrimeGlobal 100+ countries); no law-firm alliance evidence. [Low] https://www.incorp.asia/about/our-partners/ | X16: yes — Corporate secretarial, accounting, tax, payroll, immigration. https://www.incorp.asia/ | Y16: Low - recurring secretarial/accounting model. | Z16: not found | AA16: +65 8699 8821 (WhatsApp) | AB16: https://www.incorp.asia/contact-us/ | AC16: unclear | AD16: Medium | AE16: Wendy Wang — Group CEO, InCorp Global (leadership page, snapshot ~14 months old) (Medium) https://www.incorp.asia/about/our-leadership/ Lennard Yong — Group CEO, Ascentium (April 2025 release); Chairman of InCorp Global (2024) (Medium) https://kyodonewsprwire.jp/release/202504097131 | AF16: No clear mutual model: APAC-only footprint, no Moldova/Europe demand evidence. Revisit at Ascentium group level (Cyprus/UK fiduciary) if needed. | AG16: 2026-10-08
