Workbook

Sheet Рейтинг
A1: Ранг | B1: TOP-5 | C1: Компания | D1: Штаб-квартира | E1: Сайт | F1: Сегмент | G1: Группа | H1: Молдова в каталоге | I1: Доказательство по Молдове | J1: Источник (Молдова) | K1: Юрисдикции (кол-во) | L1: Юрисдикции (примеры) | M1: Источник (юрисдикции) | N1: Партнёрская программа | O1: Детали программы | P1: Источник (программа) | Q1: Email | R1: Телефон | S1: Страница контактов | T1: Адрес | U1: Источник контактов | V1: Почему подходит Legitimus | W1: Риски / проверить | X1: Признаки активности | Y1: Уровень проверки | Z1: Клиенты | AA1: Партнёрство | AB1: Молдова | AC1: Доступность | AD1: Масштаб | AE1: Итоговый балл
A2: =RANK(AE2,$AE$2:$AE$21)+COUNTIF($AE$2:AE2,AE2)-1 -> 1 | B2: =IF(A2<=5,"TOP-5","") -> TOP-5 | C2: Accace | D2: Slovakia (Bratislava) | E2: https://accace.com | F2: CEE-rooted outsourcing / corporate & secretarial, accounting, payroll, tax; market entry | G2: =IF(H2="Да","B","A") -> B | H2: Да | I2: Accace has dedicated Moldova pages: 'Corporate and secretarial services in Moldova' (go-to-market research, business setup, tax registration, business permits, work/residence permits, bank account opening, corporate changes) and 'Accounting and reporting services in Moldova'. Moldova office address NOT found in snippets; unclear whether own office or partner-delivered (Accace states other locations are covered via its partner network). | J2: https://www.accace.com/locations/moldova/corporate-and-secretarial-services/ ; https://www.accace.com/locations/moldova/accounting-and-reporting-services/ (found via WebSearch; page itself could not be fetched) | K2: 60+ jurisdictions (per Accace site as reported in search snippet; older listings: ~40 / 50+) | L2: Slovakia, Czech Republic, Hungary, Poland, Romania, Ukraine, Serbia, Moldova, South Africa, United Kingdom | M2: WebSearch snippets: https://www.amcham.ro/company/accace-outsourcing ; https://accace.com/locations/serbia/corporate-and-secretarial-services ; https://accace.com/locations/romania/corporate-and-secretarial-services ; https://accace.com/?p=252658 (Kyiv) | N2: Да | O2: Accace Circle - a 'co-created business community of like-minded BPO providers and advisors' offering unified services under one account management; Accace also states locations outside own branches are 'covered via Accace's trusted network of partners'. Contact named publicly: Business Development & Community Lead. No public application form found. Type: local-provider network. | P2: https://circle.accace.com/ ; https://accace.com/accace-circle-new-markets-within-your-reach-press-release/ (via WebSearch) | Q2: slovakia@accace.com (Slovak office, per third-party directory - not verified on accace.com); czechrepublic@accace.com (Czech office) | R2: +421 2 325 530 00 (Slovakia, per directory - not verified on own site); +420 222 753 480 (Czech) | S2: not verified (accace.com unreachable from research environment) | T2: Twin City C, Mlynske Nivy 16, 821 09 Bratislava, Slovakia (per Accace newsroom/PitchBook; FinStat shows Accace Management s.r.o. seat moved to Pribinova 40, 811 09 Bratislava in Oct 2024 - conflicting) | U2: https://accace.com/accace-slovakia-is-present-in-three-locations ; https://pitchbook.com/profiles/advisor/539638-66 ; https://finstat.sk/35873639/obchodny_register (via WebSearch) | V2: Strongest fit: CEE-focused, already sells Moldova corporate/accounting services and explicitly operates a partner network (Accace Circle) of local BPO/advisory providers. If Moldova is partner-delivered, Legitimus could become/compete to be the Moldovan legal partner; at minimum a local-counsel referral source. | X2: Live indexed pages incl. Moldova service pages and Accace Circle site; 7,000+ professionals claim | Y2: Поисковая выдача по оф. домену; сайт не открыт | Z2: 5 | AA2: 5 | AB2: 4 | AC2: 3 | AD2: 4 | AE2: =ROUND(Z2*Методика!$B$3+AA2*Методика!$B$4+AB2*Методика!$B$5+AC2*Методика!$B$6+AD2*Методика!$B$7,2) -> 4.45
A3: =RANK(AE3,$AE$2:$AE$21)+COUNTIF($AE$2:AE3,AE3)-1 -> 2 | B3: =IF(A3<=5,"TOP-5","") -> TOP-5 | C3: BridgeWest (BridgeWest Legal Network) | D3: Cyprus (Nicosia, per third-party profile; not verified on own site) | E3: https://bridgewest.eu | F3: International company formation, legal, financial and immigration services via affiliate network | G3: =IF(H3="Да","B","A") -> B | H3: Да | I3: Dedicated page: agents assist local and foreign investors to register SMEs in Moldova, offer ready-made Moldovan companies and VAT registration. | J3: https://bridgewest.eu/company-formation-moldova/ | K3: "over 70 jurisdictions" (own claim) | L3: Moldova; Cambodia; EU countries (VAT registration); Singapore (affiliate OpenCompanySingapore.com); Thailand (affiliate ThaiCompanyFormation.com); Ireland (LawyersIreland.eu) | M3: https://bridgewest.eu/ ; https://directory.partner.io/bridgewest-eu | N3: Да | O3: Delivers services through a network of independent Affiliates (law firms, consultants, accountants) in 70+ countries; homepage has a 'Join Our Network' section. Application terms not verified. | P3: https://bridgewest.eu/ | Q3: office@bridgewest.eu | R3: +44 203 287 0408 (other number shown as '+35 699 699 405' - prefix incomplete, not verified) | S3: https://bridgewest.eu/contact/ | T3: not verified | U3: https://bridgewest.eu/contact/ (search snippet) | V3: Network model built on independent local affiliates and already sells Moldova - ideal profile for Legitimus to become (or replace) the Moldova affiliate. Smaller firm, so easier to reach decision makers. | X3: Live site indexed with Moldova and other jurisdiction pages; exact recency not verified | Y3: Поисковая выдача по оф. домену; сайт не открыт | Z3: 5 | AA3: 5 | AB3: 4 | AC3: 4 | AD3: 2 | AE3: =ROUND(Z3*Методика!$B$3+AA3*Методика!$B$4+AB3*Методика!$B$5+AC3*Методика!$B$6+AD3*Методика!$B$7,2) -> 4.35
A4: =RANK(AE4,$AE$2:$AE$21)+COUNTIF($AE$2:AE4,AE4)-1 -> 3 | B4: =IF(A4<=5,"TOP-5","") -> TOP-5 | C4: Commitbiz | D4: UAE | E4: https://www.commitbiz.com | F4: Business setup, accounting, corporate secretarial and IP services; UAE + GCC formation with offices in Europe (UK, Italy, Romania, Russia) | G4: =IF(H4="Да","B","A") -> A | H4: Нет | I4: Site search for Moldova only returned UAE double-tax-treaty lists that include Moldova; no Moldova formation page. Notably lists an office in Bucharest, Romania (Moldova's neighbour). | J4: https://www.commitbiz.com/tax-residency-certificate-uae | K4: not stated; formation pages found for UAE, Qatar, Bahrain; offices in ~10 countries | L4: UAE (Dubai mainland, free zones, JAFZA/RAK offshore, DIFC, ADGM); Qatar; Bahrain; Oman (Muscat office); offices: London, Naples, Bucharest, Moscow | M4: https://www.commitbiz.com/qa/company-formation-in-qatar ; https://www.commitbiz.com/bh/company-registration-in-bahrain ; https://www.commitbiz.com/contact-us | N4: Да | O4: Refer & Earn / Referral Agreement (referral): terms page describes lead passing between independent associates, 7-day accept/decline window, 30-day termination notice. | P4: https://www.commitbiz.com/refer-and-earn-terms-conditions | Q4: info@commitbiz.com | R4: +971 4 871 4159 (main); +971 4 386 7444 (contact page title) | S4: https://www.commitbiz.com/contact-us | T4: Commitbiz LLC, 10th floor, Dubai World Trade Center, Sheikh Zayed Road, P.O. Box 293816, Dubai, UAE. Other listed offices: Abu Dhabi, Sharjah, Muscat, Bahrain, Doha, London (Dashwood House, 69 Old Broad St), Moscow, Naples, Bucharest (Bd. Maresal Alexandru Averescu 8-10). | U4: https://www.commitbiz.com/contact-us | V4: Strongest regional fit in this batch: offices in Bucharest, Moscow and Italy show an Eastern Europe/CIS client base, and it has a formal B2B referral agreement. Legitimus could be the Moldova node next to the Romania office. | X4: Live site with 2026 content ('Dubai Mainland Company Formation cost (2026)'). | Y4: Поисковая выдача по оф. домену; сайт не открыт | Z4: 4 | AA4: 4 | AB4: 5 | AC4: 4 | AD4: 3 | AE4: =ROUND(Z4*Методика!$B$3+AA4*Методика!$B$4+AB4*Методика!$B$5+AC4*Методика!$B$6+AD4*Методика!$B$7,2) -> 4.15
A5: =RANK(AE5,$AE$2:$AE$21)+COUNTIF($AE$2:AE5,AE5)-1 -> 4 | B5: =IF(A5<=5,"TOP-5","") -> TOP-5 | C5: Virtuzone | D5: UAE | E5: https://virtuzone.com | F5: UAE business setup (mainland/free zone) + offshore/international jurisdictions; part of Ascentium group (Singapore) since 2025 | G5: =IF(H5="Да","B","A") -> A | H5: Нет | I5: Offshore jurisdictions page lists Singapore, HK, KSA, BVI, Cayman only. Site search for Moldova returned only a blog article on CIS business opportunities (lists Moldova as CIS member) and a visa-free list; no Moldova formation service. Note: Virtuzone announced JV 'Virtuzone CIS' with Seven Pillars Law at AIFC (Astana, Kazakhstan) - c.2020, current status unclear. | J5: https://virtuzone.com/blog/untapped-potential-business-opportunities-cis ; https://virtuzone.com/press-release/virtuzone-and-seven-pillars-law-create-joint-venture-virtuzone-cis/ | K5: not stated as a number; UAE (all free zones/mainland) + 5 named international jurisdictions on offshore page; parent Ascentium described as 27 markets / 58 cities | L5: UAE (mainland, free zones, ADGM); Singapore; Hong Kong; Saudi Arabia; British Virgin Islands; Cayman Islands | M5: https://virtuzone.com/offshore-jurisdictions/ | N5: Да | O5: Virtuzone Referral Platform (referral type): register for personal referral link; payout after referred client buys; up to AED 3,000 per business-setup referral, AED 1,500 per corporate-services referral; no cap. Also 'Our Business & Digital Partners' page (vendor partners e.g. Payoneer) and past JVs (Virtuzone CIS, Virtuzone Israel). | P5: https://referral.virtuzone.com/ ; https://virtuzone.com/our-partners/ | Q5: info@virtuzone.com | R5: +971 4 457 8200 (WhatsApp +971 4 457 8220); 800-VIRTUZONE | S5: https://virtuzone.com/contactus | T5: Al Saaha Office B, 404, Souk Al Bahar, Burj Khalifa District, Dubai, UAE | U5: https://virtuzone.com/contactus ; https://virtuzone.com/faq/ | V5: Large, well-known UAE formation brand with a CIS-oriented history (Virtuzone CIS JV) and a now-global parent (Ascentium, 27 markets), but its referral scheme is aimed at inbound UAE clients. Best angle: Legitimus as Moldova/CIS-Europe local counsel for Ascentium/Virtuzone clients, plus reverse referrals of Moldovan founders wanting UAE companies. | W5: В задании был указан домен vzone.ae, это посторонний сайт; правильный домен virtuzone.com | X5: Live site with 2025-2026 content (VARA 2025, Sharjah Law No.3 of 2025, 'joined Ascentium in 2025'). | Y5: Поисковая выдача по оф. домену; сайт не открыт | Z5: 4 | AA5: 4 | AB5: 4 | AC5: 4 | AD5: 5 | AE5: =ROUND(Z5*Методика!$B$3+AA5*Методика!$B$4+AB5*Методика!$B$5+AC5*Методика!$B$6+AD5*Методика!$B$7,2) -> 4.1
A6: =RANK(AE6,$AE$2:$AE$21)+COUNTIF($AE$2:AE6,AE6)-1 -> 5 | B6: =IF(A6<=5,"TOP-5","") -> TOP-5 | C6: Uniwide | D6: Latvia origin (Riga office est. 2014); head office now Dubai, UAE | E6: https://www.uniwide.com | F6: International company formation, bank account support, registered office, compliance, accounting (incl. offshore) | G6: =IF(H6="Да","B","A") -> A | H6: Не найдено (неясно) | I6: No Moldova page found in searches; full jurisdiction list not retrievable. | J6: not found (search 'uniwide.com Moldova' returned nothing from uniwide.com) | K6: 30+ jurisdictions (via own offices and local registration agents) | L6: Cyprus, Latvia, United Kingdom, Seychelles, UAE, Hong Kong (full list not retrieved) | M6: https://www.uniwide.com/about/ ; https://www.uniwide.com/partner-programme/ ; https://www.uniwide.com/contact/ (via WebSearch) | N6: Да | O6: Partner Programme aimed at law firms, banks, payment providers and tax advisers. Two models: referral (partner introduces client, Uniwide delivers end-to-end) and subcontractor (partner keeps client communication, Uniwide delivers formation - effectively white-label). Uniwide also states it relies on 'long-standing partnerships with local registration agents in most 30+ jurisdictions'. | P6: https://www.uniwide.com/partner-programme/ ; https://www.uniwide.com/about/ (via WebSearch) | Q6: not found | R6: +371 6611 8787 (Riga); +44 (0)20 4501 0600 (London); +248 441-19-70 (Seychelles) | S6: https://www.uniwide.com/contact/ | T6: Riga: Krisjana Valdemara str. 33, office 20, Riga LV-1010, Latvia; Head office: Office 2902, HDS Tower, Cluster F, JLT, Dubai, PO Box 393879 | U6: https://www.uniwide.com/contact/ ; https://www.uniwide.com/new-uniwide-head-office-address-in-dubai/ (via WebSearch) | V6: Substitute candidate. Explicit partner programme for law firms with referral and subcontractor models, and reliance on local registration agents - Legitimus could both refer clients and offer itself as Moldova local agent. Russian-speaking/Baltic-origin client base likely overlaps with Moldova demand. | W6: Общий email не найден; связь через форму или телефоны | X6: Live contact page and newsroom (Dubai office operations update, Seychelles licence notice) | Y6: Поисковая выдача по оф. домену; сайт не открыт | Z6: 4 | AA6: 5 | AB6: 4 | AC6: 4 | AD6: 2 | AE6: =ROUND(Z6*Методика!$B$3+AA6*Методика!$B$4+AB6*Методика!$B$5+AC6*Методика!$B$6+AD6*Методика!$B$7,2) -> 4.05
A7: =RANK(AE7,$AE$2:$AE$21)+COUNTIF($AE$2:AE7,AE7)-1 -> 6 | B7: =IF(A7<=5,"TOP-5","") | C7: Healy Consultants Group (part of Hawksford) | D7: Singapore (also Dubai office) | E7: https://www.healyconsultants.com | F7: Global company formation / market entry for SMEs, multi-jurisdiction | G7: =IF(H7="Да","B","A") -> B | H7: Да | I7: Dedicated Moldova pages: 10-step incorporation process (name reservation, filing with State Registration Chamber, IDNO, bank account, tax/social registration); LLC with 1 shareholder/1 director any nationality, 12% CIT, ~2 weeks; setup cost quoted in EUR (EUR 7,950 per snippet); 2025 case study of Maltese client registering a recruitment agency in Moldova. Snippet-level only; page fetch failed. | J7: https://www.healyconsultants.com/moldova-company-registration/ ; https://www.healyconsultants.com/moldova-company-registration/client-case-studies/ ; https://www.healyconsultants.com/moldova-company-registration/accounting-legal | K7: "almost 200 different countries" (own claim) | L7: United Kingdom; BVI; Cayman Islands; Pakistan; US (Delaware, Nevada, Wyoming); Moldova | M7: https://www.healyconsultants.com/company-formation/global-company-registration/ (search snippet) | N7: Не найдена | O7: site search for referral/introducer/partner program returned nothing; no partner page found | P7: not found (WebSearch 'Healy Consultants referral partner program introducer') | Q7: healy@hawksford.com | R7: +65 6031 0332 (SG); +971 4266 4470 (Dubai) | S7: https://www.healyconsultants.com/contact-us/ | T7: 16 Raffles Quay, #32-03 Hong Leong Building, Singapore 048581 | U7: https://www.healyconsultants.com/contact-us/ (search snippet) | V7: Already sells Moldova incorporation remotely via power of attorney with local filings, so they must use Moldovan local agents/lawyers; a strong candidate for Legitimus as local counsel/execution partner. Now inside Hawksford, so partner decisions may sit at group level. | W7: Входит в Hawksford; публичной партнёрской программы нет | X7: Site indexed with 2026-dated pages ('10 steps to incorporate in Moldova in 2026'); acquired by Hawksford (Jersey-based group) - Dubai office renamed Hawksford per privatebankerinternational.com | Y7: Поисковая выдача по оф. домену; сайт не открыт | Z7: 5 | AA7: 3 | AB7: 4 | AC7: 4 | AD7: 4 | AE7: =ROUND(Z7*Методика!$B$3+AA7*Методика!$B$4+AB7*Методика!$B$5+AC7*Методика!$B$6+AD7*Методика!$B$7,2) -> 4.05
A8: =RANK(AE8,$AE$2:$AE$21)+COUNTIF($AE$2:AE8,AE8)-1 -> 7 | B8: =IF(A8<=5,"TOP-5","") | C8: Sovereign Group (The Sovereign Group) | D8: Gibraltar | E8: https://www.sovereigngroup.com | F8: Independent corporate & trust services provider; offshore/free-zone/onshore company formation, trusts, pensions | G8: =IF(H8="Да","B","A") -> A | H8: Нет | I8: WebSearch 'site:sovereigngroup.com Moldova' returned no sovereigngroup.com pages; office/jurisdiction lists in snippets contain no Moldova. Jurisdictions page could not be fetched (egress blocked). | J8: WebSearch site:sovereigngroup.com Moldova (2026-10-08) | K8: 20+ jurisdictions (own site: 'more than 20 jurisdictions'; 2025 event page: 20+ offices, 600 professionals; 'network of offices or agents in all major IFCs') | L8: BVI, Cyprus, Dubai, Gibraltar, Guernsey, Hong Kong, Isle of Man, Malta, Mauritius, Portugal, Saudi Arabia, Shanghai, Singapore, South Africa, Switzerland, Turks & Caicos, UK (Wikipedia list; snapshot) | M8: https://www.sovereigngroup.com/about-sovereign/our-history/ ; https://www.sovereigngroup.com/events/sovereign-at-going-global-live-2025/ ; https://en.wikipedia.org/wiki/Sovereign_Group (search snippets only) | N8: Не найдена | O8: Searches for introducer/referral/partner programme on sovereigngroup.com found nothing. Group says it works via 'offices or agents' in IFCs (agent network model), so introducer relations likely handled ad hoc via general enquiries. | P8: not found (WebSearch 2026-10-08) | Q8: info@SovereignGroup.com (general); gib@SovereignGroup.com (Gibraltar office) | R8: +350 200 76173 (Sovereign Trust (Gibraltar) Ltd) | S8: https://www.sovereigngroup.com/contact-us/ | T8: Sovereign Place, 117 Main Street, Gibraltar | U8: https://www.sovereigngroup.com/contact-us/ ; https://www.sovereigngroup.com/offices/gibraltar/ (search snippets) | V8: Large independent CSP using a mix of own offices and local agents; no CEE/CIS office visible, so a Moldova local-counsel/agent role is plausible. Scale and Gibraltar/UK client base make it a credible referral source, but no formal introducer program is public. | X8: Indexed 2025 event page (Going Global Live 2025) on sovereigngroup.com; live contact/office pages in index. Site not fetched directly (egress proxy 403). | Y8: Поисковая выдача по оф. домену; сайт не открыт | Z8: 4 | AA8: 3 | AB8: 4 | AC8: 4 | AD8: 5 | AE8: =ROUND(Z8*Методика!$B$3+AA8*Методика!$B$4+AB8*Методика!$B$5+AC8*Методика!$B$6+AD8*Методика!$B$7,2) -> 3.85
A9: =RANK(AE9,$AE$2:$AE$21)+COUNTIF($AE$2:AE9,AE9)-1 -> 8 | B9: =IF(A9<=5,"TOP-5","") | C9: Eurofast | D9: Cyprus (Nicosia) | E9: https://eurofast.eu | F9: Regional business advisory: tax, accounting, corporate/legal support, company formation in SE Europe, Middle East, Baltics | G9: =IF(H9="Да","B","A") -> A | H9: Нет | I9: Office lists found include Bucharest, Kyiv, Tbilisi but not Chisinau; 'site:eurofast.eu Moldova' returned nothing. | J9: https://bkr.com/firm/eurofast-ltd/ (office list; via WebSearch); site search returned nothing | K9: Presence in 21+ cities across Southeast Europe, Middle East and Baltics (~19 countries) | L9: Cyprus, Greece, Bulgaria, Romania (Bucharest), Serbia, Montenegro, Albania, North Macedonia, Croatia, Slovenia, Kosovo, Bosnia & Herzegovina, Egypt, Georgia (Tbilisi), Ukraine (Kyiv), Lithuania (Vilnius), Estonia (Tallinn), UAE (Dubai) | M9: https://bkr.com/firm/eurofast-ltd/ ; https://career.auth.gr/companies/eurofast/ (via WebSearch; office lists differ by source) | N9: Сеть (неформально) | O9: Eurofast Ltd is a member firm of BKR International (independent accounting/advisory network) and listed on PrimeGlobal; historically Taxand member in Cyprus. No public referral/partner programme found. | P9: https://bkr.com/firm/eurofast-ltd/ ; https://www.primeglobal.net/firms/eurofast (via WebSearch) | Q9: info@eurofast.eu (per third-party career site profile - not verified on eurofast.eu) | R9: +357 22 699 000 (Nicosia, per BKR directory) | S9: not verified | T9: Cypress Centre, 5 Chytron Street, CY-1075 Nicosia (Lefkosia), Cyprus | U9: https://bkr.com/firm/eurofast-ltd/ ; https://career.auth.gr/companies/eurofast/ (via WebSearch) | V9: Good regional fit: covers Romania, Ukraine, Georgia, Baltics but not Moldova, and works cross-border in the Balkans/Black Sea region. Moldova is a natural gap; Legitimus could serve as their Moldova correspondent. | W9: Последние датированные новости 2022 г.: проверить, активен ли сайт | X9: Listed in BKR International directory; latest dated news found 2022 (CFI.co award). No 2025-2026 news found - operating status likely but not freshly verified. | Y9: Поисковая выдача по оф. домену; сайт не открыт | Z9: 4 | AA9: 3 | AB9: 5 | AC9: 3 | AD9: 3 | AE9: =ROUND(Z9*Методика!$B$3+AA9*Методика!$B$4+AB9*Методика!$B$5+AC9*Методика!$B$6+AD9*Методика!$B$7,2) -> 3.8
A10: =RANK(AE10,$AE$2:$AE$21)+COUNTIF($AE$2:AE10,AE10)-1 -> 9 | B10: =IF(A10<=5,"TOP-5","") | C10: TMF Group | D10: Netherlands (Amsterdam) | E10: https://www.tmf-group.com | F10: Global corporate secretarial, accounting, HR/payroll, entity management, market entry (enterprise) | G10: =IF(H10="Да","B","A") -> A | H10: Нет | I10: Europe locations list (35) includes Romania and Ukraine but not Moldova; site-restricted search 'site:tmf-group.com Moldova' returned nothing from tmf-group.com. | J10: https://www.tmf-group.com/en/locations/emea (via WebSearch); no Moldova page found | K10: 87 jurisdictions, 125+ offices (Europe: 35 locations) | L10: Austria, Belgium, Bulgaria, Croatia, Cyprus, Czech Republic, Denmark, Netherlands, Poland, Romania, Ukraine, United Kingdom, Latvia, Lithuania, Estonia (2026 via Nordgain acquisition) | M10: https://www.tmf-group.com/en/locations/ ; https://www.tmf-group.com/en/locations/emea (via WebSearch) | N10: Не найдена | O10: Searches for TMF Group partner/referral/introducer programme returned only an Ashoka CSR partnership. No public referral or local-provider partner programme found. | P10: https://ashoka.org/en/partner/tmf-group (only partner-related result) | Q10: not found | R10: +31 20 575 5600 (third-party ZoomInfo listing only - not verified on own site) | S10: not verified | T10: Luna ArenA, Herikerbergweg 238, 1101 CM Amsterdam, Netherlands | U10: https://www.tmf-group.com/en/locations/emea/netherlands ; https://annualreport.tmf-group.com/search/3001011 (via WebSearch) | V10: Huge network with Romania and Ukraine but no Moldova - genuine gap Legitimus could fill for clients needing Moldova. However TMF operates own entities and has no public partner programme, so approach would need to be via CEE regional management (e.g. Romania office). | X10: Acquired Nordgain (Oct 2025), expanded into Estonia (Mar 2026) per Baltic Times; live locations pages | Y10: Поисковая выдача по оф. домену; сайт не открыт | Z10: 4 | AA10: 2 | AB10: 4 | AC10: 2 | AD10: 5 | AE10: =ROUND(Z10*Методика!$B$3+AA10*Методика!$B$4+AB10*Методика!$B$5+AC10*Методика!$B$6+AD10*Методика!$B$7,2) -> 3.4
A11: =RANK(AE11,$AE$2:$AE$21)+COUNTIF($AE$2:AE11,AE11)-1 -> 10 | B11: =IF(A11<=5,"TOP-5","") | C11: Vistra (incl. Tricor; acquired Biz Latin Hub) | D11: Hong Kong | E11: https://www.vistra.com | F11: Global corporate, fund and private-client services; international expansion | G11: =IF(H11="Да","B","A") -> A | H11: Нет | I11: WebSearch 'site:vistra.com Moldova' returned no Vistra pages about Moldova (only a name coincidence: CFO Kris Moldovan on stocktitan.net). No Moldova in located jurisdiction pages. | J11: not found | K11: 50+ markets/jurisdictions (own pages vary: 45+ jurisdictions, 85+ offices) | L11: Hong Kong SAR; China; Poland; United Kingdom; Romania (listed on Vistra companies page, unconfirmed) | M11: https://www.vistra.com/ ; https://www.vistra.com/vistra-companies ; https://www.vistra.com/locations/emea/poland | N11: Не найдена | O11: No public referral/partner program found; historically used affiliate arrangements (e.g. Biz Latin Hub collaborated with Vistra via affiliate arrangement before acquisition). General contact form routes enquiries. | P11: https://www.bizlatinhub.com/vistra-acquires-biz-latin-hub/ | Q11: not verified (redacted in snippet) | R11: +852 2521 3661 | S11: https://www.vistra.com/contact-form | T11: 19/F, Lee Garden One, 33 Hysan Avenue, Causeway Bay, Hong Kong | U11: https://www.vistra.com/about/head-office (search snippet) | V11: Large global player with strong CEE presence (Poland, possibly Romania) but no Moldova; historically fills gaps via affiliates, so a Moldova affiliate/local-counsel slot is conceivable but hard to win at enterprise scale. | W11: Поглотила Biz Latin Hub и Tricor; крупная корпорация, выйти на нужного человека сложно | X11: Live; Tricor merged in (https://www.vistra.com/tricor-now-part-vistra); acquired Biz Latin Hub Dec 2025 and launched Vistra Latam June 2026 (cfotech.news) | Y11: Поисковая выдача по оф. домену; сайт не открыт | Z11: 4 | AA11: 2 | AB11: 4 | AC11: 2 | AD11: 5 | AE11: =ROUND(Z11*Методика!$B$3+AA11*Методика!$B$4+AB11*Методика!$B$5+AC11*Методика!$B$6+AD11*Методика!$B$7,2) -> 3.4
A12: =RANK(AE12,$AE$2:$AE$21)+COUNTIF($AE$2:AE12,AE12)-1 -> 11 | B12: =IF(A12<=5,"TOP-5","") | C12: GSL (GSL group of companies) | D12: not verified (offices London, Moscow, Nicosia, Hong Kong, Dubai etc.; main phone is Moscow +7) | E12: https://gsl.org | F12: Offshore/onshore company registration, tax, legal, banking introductions | G12: =IF(H12="Да","B","A") -> B | H12: Да | I12: Moldova page: incorporation or shelf company, registered office for 1 year, apostilled docs, secretarial, bank-account pre-approval; price EUR 2,000; 1-3 workdays for LLC with foreign participation. Also Moldova tax page. | J12: https://gsl.org/en/offshore/offshore-zones/eastern-europe/moldova/ ; https://gsl.org/en/taxes/moldova/ | K12: not stated in snippets; many offshore/onshore zones across Europe, Americas, Asia | L12: Moldova; BVI; Latvia; Gibraltar; Liechtenstein; Costa Rica; China; US (New York) | M12: https://gsl.org/en/offshore/ ; https://gsl.org/en/offshore/offshore-zones/compare/ | N12: Не найдена | O12: Site says it has 'many trusted partners in different countries' but no partner/agent programme page found. | P12: https://gsl.org/en/ | Q12: gsl@gsl.org | R12: +7 495 234 3833 | S12: https://gsl.org/en/contacts/moscow/ | T12: not verified | U12: https://gsl.org/en/contacts/moscow/ ; https://gsl.org/en/contacts/bali-indonesia/ (search snippets) | V12: Sells Moldova packages without a Moldovan office, so likely uses a local agent - a local-counsel opening. However, strong Moscow footprint raises sanctions/reputational diligence concerns for Legitimus. | W12: Телефон и присутствие в Москве: до контакта проверить санкционные и репутационные риски | X12: Live, indexed; office listing includes Hong Kong, Dubai, Riga, Bali | Y12: Поисковая выдача по оф. домену; сайт не открыт | Z12: 4 | AA12: 2 | AB12: 4 | AC12: 4 | AD12: 3 | AE12: =ROUND(Z12*Методика!$B$3+AA12*Методика!$B$4+AB12*Методика!$B$5+AC12*Методика!$B$6+AD12*Методика!$B$7,2) -> 3.4
A13: =RANK(AE13,$AE$2:$AE$21)+COUNTIF($AE$2:AE13,AE13)-1 -> 12 | B13: =IF(A13<=5,"TOP-5","") | C13: Riz & Mona Consultancy | D13: UAE | E13: https://www.rizmona.com | F13: Dubai business setup consultancy (since 2009), IFZA professional partner; international setups via associate-firm network | G13: =IF(H13="Да","B","A") -> A | H13: Нет | I13: Site search for Moldova returned only a news item on the UAE-Moldova mutual visa-free agreement (Aug 2025) and travel lists; no Moldova formation service. | J13: https://www.rizmona.com/news/uae-moldova-sign-mutual-visa-free-travel-agreement-in-abu-dhabi/ | K13: not stated; 'across the world' via associate firms; named: UAE + Singapore, Malaysia, Mauritius, KSA (plus a Turkey setup blog) | L13: UAE (mainland, free zones incl. IFZA, ADGM, JAFZA offshore); Singapore; Malaysia; Mauritius; Saudi Arabia; Turkey (blog) | M13: https://www.rizmona.com/ ; https://www.rizmona.com/who-we-are/ ; https://www.rizmona.com/blog/business-setup-in-turkey/ | N13: Не найдена | O13: No referral/affiliate page found. Site states it delivers services worldwide 'through its well established network of associate firms' (local-provider network, no application page). | P13: https://www.rizmona.com/who-we-are/ | Q13: info@rizmona.com | R13: +971 4 558 6339; WhatsApp +971 54 582 1012 | S13: https://www.rizmona.com/contact-us/ | T13: Office 2401, The Exchange Tower, Business Bay, Dubai, UAE (older page: Office 1006, Single Business Tower, SZR, PO Box 393598) | U13: https://www.rizmona.com/contact-us/ ; https://www.rizmona.com/terms-and-conditions/ | V13: Small founder-led firm that explicitly works through associate firms abroad, so it could add a Moldova associate. It has written about the UAE-Moldova visa-free deal, but its scale is modest. | X13: Live site; 'About Us (March 2026)', 2026-titled pages, Aug 2025 news. | Y13: Поисковая выдача по оф. домену; сайт не открыт | Z13: 3 | AA13: 3 | AB13: 4 | AC13: 4 | AD13: 2 | AE13: =ROUND(Z13*Методика!$B$3+AA13*Методика!$B$4+AB13*Методика!$B$5+AC13*Методика!$B$6+AD13*Методика!$B$7,2) -> 3.25
A14: =RANK(AE14,$AE$2:$AE$21)+COUNTIF($AE$2:AE14,AE14)-1 -> 13 | B14: =IF(A14<=5,"TOP-5","") | C14: Tetra Consultants | D14: Singapore | E14: https://www.tetraconsultants.com | F14: Global company registration, financial licences, bank account opening, nominee services, trademarks | G14: =IF(H14="Да","B","A") -> A | H14: Не найдено (неясно) | I14: WebSearch 'site:tetraconsultants.com Moldova' returned no tetraconsultants.com pages; full jurisdiction list could not be fetched. | J14: WebSearch site:tetraconsultants.com Moldova (2026-10-08) | K14: Not stated as a number in snippets; covers 'Asia, Europe, Americas, Africa and the Middle East' | L14: Dominica, Cayman Islands, USA, Canada, Bermuda (dedicated 'Register Company' pages) | M14: https://tetraconsultants.com/ ; https://www.tetraconsultants.com/video/register-company-in-cayman-islands/ (search snippets) | N14: Не найдена | O14: No partner/referral/affiliate page surfaced in search. | P14: not found | Q14: enquiry@tetraconsultants.com | R14: not found (site footer offers WhatsApp per snippet) | S14: not verified (homepage https://tetraconsultants.com/) | T14: 67 Ubi Crescent #05-01, Techniques Centre, Singapore 408560 | U14: https://tetraconsultants.com/ (snippet) | V14: Broad multi-jurisdiction formation shop likely to rely on local partners in smaller European markets; Moldova presence unknown. Singapore HQ, not UK, though it was assigned to this batch. | X14: Live indexed homepage with anti-fraud notice, active careers pages. | Y14: Поисковая выдача по оф. домену; сайт не открыт | Z14: 4 | AA14: 2 | AB14: 3 | AC14: 3 | AD14: 3 | AE14: =ROUND(Z14*Методика!$B$3+AA14*Методика!$B$4+AB14*Методика!$B$5+AC14*Методика!$B$6+AD14*Методика!$B$7,2) -> 3.05
A15: =RANK(AE15,$AE$2:$AE$21)+COUNTIF($AE$2:AE15,AE15)-1 -> 14 | B15: =IF(A15<=5,"TOP-5","") | C15: Shuraa Business Setup | D15: UAE | E15: https://www.shuraa.com | F15: UAE business setup (mainland, free zone, offshore), IFZA professional partner; offices abroad (UK, Netherlands, India) | G15: =IF(H15="Да","B","A") -> A | H15: Нет | I15: Site search for Moldova returned only visa-free travel lists for UAE residents; no Moldova formation page. No non-UAE formation jurisdiction list found. | J15: https://www.shuraa.com/visa-free-countries-for-uae-residents/ | K15: not stated; formation found only in UAE (mainland, free zones, JAFZA/RAK offshore). Claims >100,000 companies registered in UAE. | L15: Dubai mainland; UAE free zones (Sharjah, Abu Dhabi, Ajman, RAK, Fujairah); JAFZA offshore; RAK ICC offshore | M15: https://www.shuraa.com/uae-offshore-company-formation/ ; https://www.shuraa.com/about/ | N15: Да | O15: Shuraa Refer & Earn programme (referral): up to AED 3,000 per successful introduction, paid after completed mainland/free zone setup; referrers may not represent Shuraa or sign agreements. | P15: https://referral.shuraa.com/ ; https://referral.shuraa.com/terms-and-conditions | Q15: info@shuraa.com (UK: info@shuraa.co.uk) | R15: +971 4 408 1900; toll-free 800-SHURAA; WhatsApp +971 50 777 5554 | S15: https://www.shuraa.com/contact-us/ | T15: Office 501, 5th Floor, Aspin Commercial Tower, Sheikh Zayed Road, Dubai, UAE, P.O. Box 78029. Other offices listed: 85 Uxbridge Road, Ealing, London W5 5BW (UK); Amsterdam (NL); Delhi (IN). | U15: https://www.shuraa.com/contact-us/ | V15: Big UAE-inbound formation house with offices in London/Amsterdam/Delhi used for client acquisition rather than foreign incorporation. Fit is mostly reverse referral (Moldovan clients to UAE) or occasional outbound referrals; low need for Moldovan counsel. | X15: Live site with 2026-dated pages ('Business Setup in Dubai and the UAE 2026', 'Best Countries to Start a Business in 2026'). | Y15: Поисковая выдача по оф. домену; сайт не открыт | Z15: 2 | AA15: 3 | AB15: 2 | AC15: 4 | AD15: 5 | AE15: =ROUND(Z15*Методика!$B$3+AA15*Методика!$B$4+AB15*Методика!$B$5+AC15*Методика!$B$6+AD15*Методика!$B$7,2) -> 2.75
A16: =RANK(AE16,$AE$2:$AE$21)+COUNTIF($AE$2:AE16,AE16)-1 -> 15 | B16: =IF(A16<=5,"TOP-5","") | C16: SFM Corporate Services (SFM Offshore) | D16: Switzerland (offices also Dubai, Seychelles, Hong Kong; sources conflict) | E16: https://www.sfmoffshore.com | F16: Offshore company formation, UAE free zones, nominee services, bank account opening, UAE residency, trusts/foundations | G16: =IF(H16="Да","B","A") -> A | H16: Не найдено (неясно) | I16: WebSearch 'site:sfmoffshore.com Moldova' returned nothing; own jurisdiction list not fetched. | J16: WebSearch site:sfmoffshore.com Moldova (2026-10-08) | K16: ~50 (third-party directory figure; not verified on own site) | L16: BVI, Seychelles, Delaware, Hong Kong, Singapore, UAE free zones (DIFC, DMCC, RAK ICC, JAFZA), Panama foundations | M16: https://www.jasminedirectory.com/business-marketing/detail,1856595773,sfm.html (third-party snippet) | N16: Не найдена | O16: Searches for SFM introducer/partner/affiliate program returned nothing. | P16: not found | Q16: not verified | R16: not verified | S16: not verified | T16: 13th Floor, Capricorn Tower, Sheikh Zayed Road, Dubai, UAE (Feefo listing, third-party) | U16: https://feefo.com/fr-CA/reviews/sfm-offshore | V16: Offshore/UAE-centred retail formation agent; Moldova not visible. Possible minor referral source for clients wanting an onshore European/nearshore entity, but contacts are unverified. | X16: Active Feefo review profile with many pages of reviews; directory listings. Own site not fetched. | Y16: Поисковая выдача по оф. домену; сайт не открыт | Z16: 3 | AA16: 2 | AB16: 3 | AC16: 2 | AD16: 3 | AE16: =ROUND(Z16*Методика!$B$3+AA16*Методика!$B$4+AB16*Методика!$B$5+AC16*Методика!$B$6+AD16*Методика!$B$7,2) -> 2.65
A17: =RANK(AE17,$AE$2:$AE$21)+COUNTIF($AE$2:AE17,AE17)-1 -> 16 | B17: =IF(A17<=5,"TOP-5","") | C17: Creation Business Consultants | D17: UAE | E17: https://www.creationbc.com | F17: GCC market-entry / corporate services (UAE, KSA and wider GCC), offices in Dubai, DIFC, Riyadh, Hong Kong | G17: =IF(H17="Да","B","A") -> A | H17: Нет | I17: Locations page/menu lists GCC, Egypt, HK, China, UK, AU, USA, KR and offshore islands; no Moldova. Site search for Moldova returned no relevant pages. | J17: https://www.creationbc.com/locations/ | K17: 'over 10 countries' (locations page) | L17: UAE; Saudi Arabia; Kuwait; Bahrain; Oman; Qatar; Egypt; Hong Kong; BVI; Cayman Islands; Seychelles; Mauritius; Saint Kitts | M17: https://www.creationbc.com/locations/ | N17: Не найдена | O17: Searches for partner/referral/affiliate on site returned no program; only a careers listing mentioning 'referral partners'. | P17: not found | Q17: info@creationbc.com | R17: +971 4 878 6240 (Dubai); +966 11 434 3300 (Riyadh) | S17: https://www.creationbc.com/contact-us/ | T17: Office 2102, Cheddar Cheese Tower (O-14 Tower), Business Bay, Dubai, UAE (older pages: Prism Tower Office 2308); DIFC: Level 1, Innovation One; Riyadh: 5115 An Narjis, Prince Faisal Ibn Bandar Ibn Abdulaziz Rd, Riyadh 13324 | U17: https://www.creationbc.com/our-team/ ; https://www.creationbc.com/contact-us/ ; https://www.creationbc.com/en-sa/contact-us/ | V17: Serious mid-size market-entry firm with a GCC/Asia focus and no Eastern Europe coverage. Weak natural fit; possible only as an outbound referral counterpart for Moldovan clients entering the GCC. | X17: Live site; Hong Kong office announced 9 May 2024; 2026-era news posts. | Y17: Поисковая выдача по оф. домену; сайт не открыт | Z17: 3 | AA17: 2 | AB17: 2 | AC17: 4 | AD17: 3 | AE17: =ROUND(Z17*Методика!$B$3+AA17*Методика!$B$4+AB17*Методика!$B$5+AC17*Методика!$B$6+AD17*Методика!$B$7,2) -> 2.6
A18: =RANK(AE18,$AE$2:$AE$21)+COUNTIF($AE$2:AE18,AE18)-1 -> 17 | B18: =IF(A18<=5,"TOP-5","") | C18: Avyanco | D18: UAE | E18: https://avyanco.com | F18: Dubai business setup + accounting/compliance; also UK limited company and Saudi MISA setups; desks in London and Ahmedabad | G18: =IF(H18="Да","B","A") -> A | H18: Нет | I18: Site search for Moldova returned only unrelated UAE service pages; no Moldova page. | J18: not found (site search avyanco.com 'Moldova') | K18: not stated; UAE + UK + Saudi Arabia (+ BVI guide) | L18: UAE (mainland, free zones: Meydan, RAKEZ, DUQE, SAIF, UAQ FTZ); United Kingdom (Companies House Ltd); Saudi Arabia (MISA); BVI (guide) | M18: https://avyanco.com/ ; https://avyanco.com/business-setup-in-saudi-arabia/ ; https://avyanco.com/bvi-company-formation-guide/ | N18: Не найдена | O18: No referral/affiliate page found in site searches; contact page titled 'Talk to a Partner' (refers to firm partners, not a program). | P18: not found | Q18: info@avyanco.com | R18: +971 50 398 9000 (Dubai); +44 7404 022740 (UK desk) | S18: https://avyanco.com/contact-us/ | T18: Level 36, Burj Al Salam Tower, Trade Center First, Sheikh Zayed Road, Dubai, UAE; UK desk: Regus Harrow, 79 College Road, Harrow HA1 1BD | U18: https://avyanco.com/contact-us/ ; https://avyanco.com/terms-conditions/ | V18: Mid-size Dubai firm with a modest international offer (UK, KSA) and no CEE presence. Limited fit; possible ad-hoc referrals. | X18: Live site; 2026 BVI guide; DED licence 909402 (Avyanco Business Consultancy LLC). | Y18: Поисковая выдача по оф. домену; сайт не открыт | Z18: 2 | AA18: 2 | AB18: 3 | AC18: 4 | AD18: 2 | AE18: =ROUND(Z18*Методика!$B$3+AA18*Методика!$B$4+AB18*Методика!$B$5+AC18*Методика!$B$6+AD18*Методика!$B$7,2) -> 2.45
A19: =RANK(AE19,$AE$2:$AE$21)+COUNTIF($AE$2:AE19,AE19)-1 -> 18 | B19: =IF(A19<=5,"TOP-5","") | C19: InCorp Global (rebranding to Ascentium) | D19: Singapore | E19: https://www.incorp.asia | F19: APAC corporate services: incorporation, corporate secretarial, accounting/tax, payroll, immigration | G19: =IF(H19="Да","B","A") -> A | H19: Нет | I19: Market list is APAC-only (9 markets) with no Moldova; WebSearch 'site:incorp.asia Moldova' returned no incorp.asia pages (only unrelated incorpore.md). | J19: https://www.incorp.asia/about/ | K19: 9 APAC markets (some pages still say 8); ~20 offices + 7 in China | L19: Singapore; Australia; Hong Kong SAR; India; Indonesia; Mainland China; Malaysia; Philippines; Vietnam | M19: https://www.incorp.asia/about/ ; https://www.incorp.asia/press-releases/incorp-global-expands-its-footprint-in-hong-kong/ | N19: Не найдена | O19: No InCorp Global partner/referral page found. Note: the 20%-commission referral program at incorp.com is a different US company (InCorp Services) - not this firm. ACE Singapore member discount (15%) exists but is a perk, not a referral program. | P19: https://ace.org.sg/startup-support-pack/incorp-global/ | Q19: not found | R19: +65 8699 8821 (WhatsApp) | S19: https://www.incorp.asia/contact-us/ | T19: 36 Robinson Road, #20-01 City House, Singapore 068877 | U19: https://www.incorp.asia/contact-us/ (search snippet) | V19: Pure APAC footprint, no Europe/CIS coverage; Moldova referrals would be rare and only for Asian clients going to Europe. Low strategic fit beyond an occasional outbound referral. | W19: Не путать с InCorp Services (США, incorp.com), у которой есть реферальная программа 20% | X19: Live, indexed press releases; About page states rebranding to Ascentium; 1,500+ staff, 20,000+ clients claimed | Y19: Поисковая выдача по оф. домену; сайт не открыт | Z19: 2 | AA19: 2 | AB19: 2 | AC19: 3 | AD19: 4 | AE19: =ROUND(Z19*Методика!$B$3+AA19*Методика!$B$4+AB19*Методика!$B$5+AC19*Методика!$B$6+AD19*Методика!$B$7,2) -> 2.3
A20: =RANK(AE20,$AE$2:$AE$21)+COUNTIF($AE$2:AE20,AE20)-1 -> 19 | B20: =IF(A20<=5,"TOP-5","") | C20: Sleek | D20: Singapore | E20: https://sleek.com | F20: Digital company incorporation, corporate secretary, accounting for SMEs/startups | G20: =IF(H20="Да","B","A") -> A | H20: Нет | I20: Only 4 markets; WebSearch 'site:sleek.com Moldova' returned no sleek.com pages. | J20: not found | K20: 4 (Singapore, Hong Kong, Australia, UK) | L20: Singapore; Hong Kong; Australia; United Kingdom | M20: https://sleek.com/sg/about/ ; https://sleek.com/sg/ | N20: Да | O20: Affiliate partners programme: SGD 300 per successful conversion + SGD 1,000 bonus per 10 conversions; open to communities/creators with SME audiences; new countries on request via affiliates@sleek.com. Also 'Partner perks' page for third-party vendors. | P20: https://sleek.com/sg/affiliates/ ; https://sleek.com/sg/our-trusted-partners/ | Q20: affiliates@sleek.com (affiliate programme); general email not found | R20: +65 6929 8273 | S20: https://sleek.com/sg/ (Contact Sales in navigation) | T20: not found | U20: https://sleek.com/sg/affiliates/ (search snippet) | V20: Only 4 home markets, no Eastern Europe; inbound affiliate programme pays for referrals TO Sleek, not out. Little Moldova demand; low fit. | X20: Live; 2026-dated HK incorporation guide indexed (https://sleek.com/hk/resources/sleek-hong-kong-incorporation-overview/) | Y20: Поисковая выдача по оф. домену; сайт не открыт | Z20: 2 | AA20: 3 | AB20: 1 | AC20: 4 | AD20: 3 | AE20: =ROUND(Z20*Методика!$B$3+AA20*Методика!$B$4+AB20*Методика!$B$5+AC20*Методика!$B$6+AD20*Методика!$B$7,2) -> 2.3
A21: =RANK(AE21,$AE$2:$AE$21)+COUNTIF($AE$2:AE21,AE21)-1 -> 20 | B21: =IF(A21<=5,"TOP-5","") | C21: IQ-EQ | D21: Luxembourg | E21: https://iqeq.com | F21: Fund administration, corporate, trust & private client services (institutional/fund focus) | G21: =IF(H21="Да","B","A") -> A | H21: Нет | I21: No Moldova (nor Romania/Ukraine) presence found; 'site:iqeq.com Moldova' returned nothing from iqeq.com. Full locations list could not be fetched. | J21: not found (site search returned nothing; https://iqeq.com/locations/ not fetchable) | K21: 25 jurisdictions | L21: Luxembourg, United States, Mainland China, Hong Kong, India, Japan, Singapore, UAE (Europe/Africa/Middle East coverage stated) | M21: https://iqeq.foleon.com/brochure/hybrid-funds/about-iq-eq ; https://iqeq.com/careers/locations/united-states/ (via WebSearch) | N21: Не найдена | O21: No referral/introducer/partner programme found in searches. | P21: not found | Q21: not found | R21: +352 466 1111 (Luxembourg registered office) | S21: https://iqeq.com/lu/locations/luxembourg/ (location page with 'Contact us' link) | T21: 412F, route d'Esch, L-1471 Luxembourg (directories also show L-2086) | U21: https://iqeq.com/lu/locations/luxembourg/ (via WebSearch) | V21: Weak fit: fund-administration/institutional focus in major financial centres, no CEE/Moldova footprint and no partner programme. Low likelihood of Moldova referrals. | X21: Active careers postings on iqeq.com (2026); 5,800+ staff per brochure | Y21: Поисковая выдача по оф. домену; сайт не открыт | Z21: 2 | AA21: 1 | AB21: 2 | AC21: 2 | AD21: 4 | AE21: =ROUND(Z21*Методика!$B$3+AA21*Методика!$B$4+AB21*Методика!$B$5+AC21*Методика!$B$6+AD21*Методика!$B$7,2) -> 1.95

Sheet Группа A – нет Молдовы
A1: Группа A: Молдова отсутствует или не найдена в опубликованном каталоге (зелёные ячейки берутся с листа «Рейтинг»)
A2: Ранг | B2: Компания | C2: Сайт | D2: Молдова | E2: Доказательство / источник | F2: Партнёрская программа | G2: Email | H2: Телефон | I2: Итоговый балл
A3: =Рейтинг!A4 -> 3 | B3: =Рейтинг!C4 -> Commitbiz | C3: =Рейтинг!E4 -> https://www.commitbiz.com | D3: =Рейтинг!H4 -> Нет | E3: =Рейтинг!I4&" | "&Рейтинг!J4 -> Site search for Moldova only returned UAE double-tax-treaty lists that include Moldova; no Moldova formation page. Notably lists an office in Bucharest, Romania (Moldova's neighbour). | https://www.commitbiz.com/tax-residency-certificate-uae | F3: =Рейтинг!N4&": "&Рейтинг!O4 -> Да: Refer & Earn / Referral Agreement (referral): terms page describes lead passing between independent associates, 7-day accept/decline window, 30-day termination notice. | G3: =Рейтинг!Q4 -> info@commitbiz.com | H3: =Рейтинг!R4 -> +971 4 871 4159 (main); +971 4 386 7444 (contact page title) | I3: =Рейтинг!AE4 -> 4.15
A4: =Рейтинг!A5 -> 4 | B4: =Рейтинг!C5 -> Virtuzone | C4: =Рейтинг!E5 -> https://virtuzone.com | D4: =Рейтинг!H5 -> Нет | E4: =Рейтинг!I5&" | "&Рейтинг!J5 -> Offshore jurisdictions page lists Singapore, HK, KSA, BVI, Cayman only. Site search for Moldova returned only a blog article on CIS business opportunities (lists Moldova as CIS member) and a visa-free list; no Moldova formation service. Note: Virtuzone announced JV 'Virtuzone CIS' with Seven Pillars Law at AIFC (Astana, Kazakhstan) - c.2020, current status unclear. | https://virtuzone.com/blog/untapped-potential-business-opportunities-cis ; https://virtuzone.com/press-release/virtuzone-and-seven-pillars-law-create-joint-venture-virtuzone-cis/ | F4: =Рейтинг!N5&": "&Рейтинг!O5 -> Да: Virtuzone Referral Platform (referral type): register for personal referral link; payout after referred client buys; up to AED 3,000 per business-setup referral, AED 1,500 per corporate-services referral; no cap. Also 'Our Business & Digital Partners' page (vendor partners e.g. Payoneer) and past JVs (Virtuzone CIS, Virtuzone Israel). | G4: =Рейтинг!Q5 -> info@virtuzone.com | H4: =Рейтинг!R5 -> +971 4 457 8200 (WhatsApp +971 4 457 8220); 800-VIRTUZONE | I4: =Рейтинг!AE5 -> 4.1
A5: =Рейтинг!A6 -> 5 | B5: =Рейтинг!C6 -> Uniwide | C5: =Рейтинг!E6 -> https://www.uniwide.com | D5: =Рейтинг!H6 -> Не найдено (неясно) | E5: =Рейтинг!I6&" | "&Рейтинг!J6 -> No Moldova page found in searches; full jurisdiction list not retrievable. | not found (search 'uniwide.com Moldova' returned nothing from uniwide.com) | F5: =Рейтинг!N6&": "&Рейтинг!O6 -> Да: Partner Programme aimed at law firms, banks, payment providers and tax advisers. Two models: referral (partner introduces client, Uniwide delivers end-to-end) and subcontractor (partner keeps client communication, Uniwide delivers formation - effectively white-label). Uniwide also states it relies on 'long-standing partnerships with local registration agents in most 30+ jurisdictions'. | G5: =Рейтинг!Q6 -> not found | H5: =Рейтинг!R6 -> +371 6611 8787 (Riga); +44 (0)20 4501 0600 (London); +248 441-19-70 (Seychelles) | I5: =Рейтинг!AE6 -> 4.05
A6: =Рейтинг!A8 -> 7 | B6: =Рейтинг!C8 -> Sovereign Group (The Sovereign Group) | C6: =Рейтинг!E8 -> https://www.sovereigngroup.com | D6: =Рейтинг!H8 -> Нет | E6: =Рейтинг!I8&" | "&Рейтинг!J8 -> WebSearch 'site:sovereigngroup.com Moldova' returned no sovereigngroup.com pages; office/jurisdiction lists in snippets contain no Moldova. Jurisdictions page could not be fetched (egress blocked). | WebSearch site:sovereigngroup.com Moldova (2026-10-08) | F6: =Рейтинг!N8&": "&Рейтинг!O8 -> Не найдена: Searches for introducer/referral/partner programme on sovereigngroup.com found nothing. Group says it works via 'offices or agents' in IFCs (agent network model), so introducer relations likely handled ad hoc via general enquiries. | G6: =Рейтинг!Q8 -> info@SovereignGroup.com (general); gib@SovereignGroup.com (Gibraltar office) | H6: =Рейтинг!R8 -> +350 200 76173 (Sovereign Trust (Gibraltar) Ltd) | I6: =Рейтинг!AE8 -> 3.85
A7: =Рейтинг!A9 -> 8 | B7: =Рейтинг!C9 -> Eurofast | C7: =Рейтинг!E9 -> https://eurofast.eu | D7: =Рейтинг!H9 -> Нет | E7: =Рейтинг!I9&" | "&Рейтинг!J9 -> Office lists found include Bucharest, Kyiv, Tbilisi but not Chisinau; 'site:eurofast.eu Moldova' returned nothing. | https://bkr.com/firm/eurofast-ltd/ (office list; via WebSearch); site search returned nothing | F7: =Рейтинг!N9&": "&Рейтинг!O9 -> Сеть (неформально): Eurofast Ltd is a member firm of BKR International (independent accounting/advisory network) and listed on PrimeGlobal; historically Taxand member in Cyprus. No public referral/partner programme found. | G7: =Рейтинг!Q9 -> info@eurofast.eu (per third-party career site profile - not verified on eurofast.eu) | H7: =Рейтинг!R9 -> +357 22 699 000 (Nicosia, per BKR directory) | I7: =Рейтинг!AE9 -> 3.8
A8: =Рейтинг!A10 -> 9 | B8: =Рейтинг!C10 -> TMF Group | C8: =Рейтинг!E10 -> https://www.tmf-group.com | D8: =Рейтинг!H10 -> Нет | E8: =Рейтинг!I10&" | "&Рейтинг!J10 -> Europe locations list (35) includes Romania and Ukraine but not Moldova; site-restricted search 'site:tmf-group.com Moldova' returned nothing from tmf-group.com. | https://www.tmf-group.com/en/locations/emea (via WebSearch); no Moldova page found | F8: =Рейтинг!N10&": "&Рейтинг!O10 -> Не найдена: Searches for TMF Group partner/referral/introducer programme returned only an Ashoka CSR partnership. No public referral or local-provider partner programme found. | G8: =Рейтинг!Q10 -> not found | H8: =Рейтинг!R10 -> +31 20 575 5600 (third-party ZoomInfo listing only - not verified on own site) | I8: =Рейтинг!AE10 -> 3.4
A9: =Рейтинг!A11 -> 10 | B9: =Рейтинг!C11 -> Vistra (incl. Tricor; acquired Biz Latin Hub) | C9: =Рейтинг!E11 -> https://www.vistra.com | D9: =Рейтинг!H11 -> Нет | E9: =Рейтинг!I11&" | "&Рейтинг!J11 -> WebSearch 'site:vistra.com Moldova' returned no Vistra pages about Moldova (only a name coincidence: CFO Kris Moldovan on stocktitan.net). No Moldova in located jurisdiction pages. | not found | F9: =Рейтинг!N11&": "&Рейтинг!O11 -> Не найдена: No public referral/partner program found; historically used affiliate arrangements (e.g. Biz Latin Hub collaborated with Vistra via affiliate arrangement before acquisition). General contact form routes enquiries. | G9: =Рейтинг!Q11 -> not verified (redacted in snippet) | H9: =Рейтинг!R11 -> +852 2521 3661 | I9: =Рейтинг!AE11 -> 3.4
A10: =Рейтинг!A13 -> 12 | B10: =Рейтинг!C13 -> Riz & Mona Consultancy | C10: =Рейтинг!E13 -> https://www.rizmona.com | D10: =Рейтинг!H13 -> Нет | E10: =Рейтинг!I13&" | "&Рейтинг!J13 -> Site search for Moldova returned only a news item on the UAE-Moldova mutual visa-free agreement (Aug 2025) and travel lists; no Moldova formation service. | https://www.rizmona.com/news/uae-moldova-sign-mutual-visa-free-travel-agreement-in-abu-dhabi/ | F10: =Рейтинг!N13&": "&Рейтинг!O13 -> Не найдена: No referral/affiliate page found. Site states it delivers services worldwide 'through its well established network of associate firms' (local-provider network, no application page). | G10: =Рейтинг!Q13 -> info@rizmona.com | H10: =Рейтинг!R13 -> +971 4 558 6339; WhatsApp +971 54 582 1012 | I10: =Рейтинг!AE13 -> 3.25
A11: =Рейтинг!A14 -> 13 | B11: =Рейтинг!C14 -> Tetra Consultants | C11: =Рейтинг!E14 -> https://www.tetraconsultants.com | D11: =Рейтинг!H14 -> Не найдено (неясно) | E11: =Рейтинг!I14&" | "&Рейтинг!J14 -> WebSearch 'site:tetraconsultants.com Moldova' returned no tetraconsultants.com pages; full jurisdiction list could not be fetched. | WebSearch site:tetraconsultants.com Moldova (2026-10-08) | F11: =Рейтинг!N14&": "&Рейтинг!O14 -> Не найдена: No partner/referral/affiliate page surfaced in search. | G11: =Рейтинг!Q14 -> enquiry@tetraconsultants.com | H11: =Рейтинг!R14 -> not found (site footer offers WhatsApp per snippet) | I11: =Рейтинг!AE14 -> 3.05
A12: =Рейтинг!A15 -> 14 | B12: =Рейтинг!C15 -> Shuraa Business Setup | C12: =Рейтинг!E15 -> https://www.shuraa.com | D12: =Рейтинг!H15 -> Нет | E12: =Рейтинг!I15&" | "&Рейтинг!J15 -> Site search for Moldova returned only visa-free travel lists for UAE residents; no Moldova formation page. No non-UAE formation jurisdiction list found. | https://www.shuraa.com/visa-free-countries-for-uae-residents/ | F12: =Рейтинг!N15&": "&Рейтинг!O15 -> Да: Shuraa Refer & Earn programme (referral): up to AED 3,000 per successful introduction, paid after completed mainland/free zone setup; referrers may not represent Shuraa or sign agreements. | G12: =Рейтинг!Q15 -> info@shuraa.com (UK: info@shuraa.co.uk) | H12: =Рейтинг!R15 -> +971 4 408 1900; toll-free 800-SHURAA; WhatsApp +971 50 777 5554 | I12: =Рейтинг!AE15 -> 2.75
A13: =Рейтинг!A16 -> 15 | B13: =Рейтинг!C16 -> SFM Corporate Services (SFM Offshore) | C13: =Рейтинг!E16 -> https://www.sfmoffshore.com | D13: =Рейтинг!H16 -> Не найдено (неясно) | E13: =Рейтинг!I16&" | "&Рейтинг!J16 -> WebSearch 'site:sfmoffshore.com Moldova' returned nothing; own jurisdiction list not fetched. | WebSearch site:sfmoffshore.com Moldova (2026-10-08) | F13: =Рейтинг!N16&": "&Рейтинг!O16 -> Не найдена: Searches for SFM introducer/partner/affiliate program returned nothing. | G13: =Рейтинг!Q16 -> not verified | H13: =Рейтинг!R16 -> not verified | I13: =Рейтинг!AE16 -> 2.65
A14: =Рейтинг!A17 -> 16 | B14: =Рейтинг!C17 -> Creation Business Consultants | C14: =Рейтинг!E17 -> https://www.creationbc.com | D14: =Рейтинг!H17 -> Нет | E14: =Рейтинг!I17&" | "&Рейтинг!J17 -> Locations page/menu lists GCC, Egypt, HK, China, UK, AU, USA, KR and offshore islands; no Moldova. Site search for Moldova returned no relevant pages. | https://www.creationbc.com/locations/ | F14: =Рейтинг!N17&": "&Рейтинг!O17 -> Не найдена: Searches for partner/referral/affiliate on site returned no program; only a careers listing mentioning 'referral partners'. | G14: =Рейтинг!Q17 -> info@creationbc.com | H14: =Рейтинг!R17 -> +971 4 878 6240 (Dubai); +966 11 434 3300 (Riyadh) | I14: =Рейтинг!AE17 -> 2.6
A15: =Рейтинг!A18 -> 17 | B15: =Рейтинг!C18 -> Avyanco | C15: =Рейтинг!E18 -> https://avyanco.com | D15: =Рейтинг!H18 -> Нет | E15: =Рейтинг!I18&" | "&Рейтинг!J18 -> Site search for Moldova returned only unrelated UAE service pages; no Moldova page. | not found (site search avyanco.com 'Moldova') | F15: =Рейтинг!N18&": "&Рейтинг!O18 -> Не найдена: No referral/affiliate page found in site searches; contact page titled 'Talk to a Partner' (refers to firm partners, not a program). | G15: =Рейтинг!Q18 -> info@avyanco.com | H15: =Рейтинг!R18 -> +971 50 398 9000 (Dubai); +44 7404 022740 (UK desk) | I15: =Рейтинг!AE18 -> 2.45
A16: =Рейтинг!A19 -> 18 | B16: =Рейтинг!C19 -> InCorp Global (rebranding to Ascentium) | C16: =Рейтинг!E19 -> https://www.incorp.asia | D16: =Рейтинг!H19 -> Нет | E16: =Рейтинг!I19&" | "&Рейтинг!J19 -> Market list is APAC-only (9 markets) with no Moldova; WebSearch 'site:incorp.asia Moldova' returned no incorp.asia pages (only unrelated incorpore.md). | https://www.incorp.asia/about/ | F16: =Рейтинг!N19&": "&Рейтинг!O19 -> Не найдена: No InCorp Global partner/referral page found. Note: the 20%-commission referral program at incorp.com is a different US company (InCorp Services) - not this firm. ACE Singapore member discount (15%) exists but is a perk, not a referral program. | G16: =Рейтинг!Q19 -> not found | H16: =Рейтинг!R19 -> +65 8699 8821 (WhatsApp) | I16: =Рейтинг!AE19 -> 2.3
A17: =Рейтинг!A20 -> 19 | B17: =Рейтинг!C20 -> Sleek | C17: =Рейтинг!E20 -> https://sleek.com | D17: =Рейтинг!H20 -> Нет | E17: =Рейтинг!I20&" | "&Рейтинг!J20 -> Only 4 markets; WebSearch 'site:sleek.com Moldova' returned no sleek.com pages. | not found | F17: =Рейтинг!N20&": "&Рейтинг!O20 -> Да: Affiliate partners programme: SGD 300 per successful conversion + SGD 1,000 bonus per 10 conversions; open to communities/creators with SME audiences; new countries on request via affiliates@sleek.com. Also 'Partner perks' page for third-party vendors. | G17: =Рейтинг!Q20 -> affiliates@sleek.com (affiliate programme); general email not found | H17: =Рейтинг!R20 -> +65 6929 8273 | I17: =Рейтинг!AE20 -> 2.3
A18: =Рейтинг!A21 -> 20 | B18: =Рейтинг!C21 -> IQ-EQ | C18: =Рейтинг!E21 -> https://iqeq.com | D18: =Рейтинг!H21 -> Нет | E18: =Рейтинг!I21&" | "&Рейтинг!J21 -> No Moldova (nor Romania/Ukraine) presence found; 'site:iqeq.com Moldova' returned nothing from iqeq.com. Full locations list could not be fetched. | not found (site search returned nothing; https://iqeq.com/locations/ not fetchable) | F18: =Рейтинг!N21&": "&Рейтинг!O21 -> Не найдена: No referral/introducer/partner programme found in searches. | G18: =Рейтинг!Q21 -> not found | H18: =Рейтинг!R21 -> +352 466 1111 (Luxembourg registered office) | I18: =Рейтинг!AE21 -> 1.95
A20: =COUNTA(B3:B18) -> 16 | B20: компаний в группе

Sheet Группа B – есть Молдова
A1: Группа B: Молдова уже предлагается
A2: Ранг | B2: Компания | C2: Сайт | D2: Молдова | E2: Доказательство / источник | F2: Партнёрская программа | G2: Email | H2: Телефон | I2: Итоговый балл
A3: =Рейтинг!A2 -> 1 | B3: =Рейтинг!C2 -> Accace | C3: =Рейтинг!E2 -> https://accace.com | D3: =Рейтинг!H2 -> Да | E3: =Рейтинг!I2&" | "&Рейтинг!J2 -> Accace has dedicated Moldova pages: 'Corporate and secretarial services in Moldova' (go-to-market research, business setup, tax registration, business permits, work/residence permits, bank account opening, corporate changes) and 'Accounting and reporting services in Moldova'. Moldova office address NOT found in snippets; unclear whether own office or partner-delivered (Accace states other locations are covered via its partner network). | https://www.accace.com/locations/moldova/corporate-and-secretarial-services/ ; https://www.accace.com/locations/moldova/accounting-and-reporting-services/ (found via WebSearch; page itself could not be fetched) | F3: =Рейтинг!N2&": "&Рейтинг!O2 -> Да: Accace Circle - a 'co-created business community of like-minded BPO providers and advisors' offering unified services under one account management; Accace also states locations outside own branches are 'covered via Accace's trusted network of partners'. Contact named publicly: Business Development & Community Lead. No public application form found. Type: local-provider network. | G3: =Рейтинг!Q2 -> slovakia@accace.com (Slovak office, per third-party directory - not verified on accace.com); czechrepublic@accace.com (Czech office) | H3: =Рейтинг!R2 -> +421 2 325 530 00 (Slovakia, per directory - not verified on own site); +420 222 753 480 (Czech) | I3: =Рейтинг!AE2 -> 4.45
A4: =Рейтинг!A3 -> 2 | B4: =Рейтинг!C3 -> BridgeWest (BridgeWest Legal Network) | C4: =Рейтинг!E3 -> https://bridgewest.eu | D4: =Рейтинг!H3 -> Да | E4: =Рейтинг!I3&" | "&Рейтинг!J3 -> Dedicated page: agents assist local and foreign investors to register SMEs in Moldova, offer ready-made Moldovan companies and VAT registration. | https://bridgewest.eu/company-formation-moldova/ | F4: =Рейтинг!N3&": "&Рейтинг!O3 -> Да: Delivers services through a network of independent Affiliates (law firms, consultants, accountants) in 70+ countries; homepage has a 'Join Our Network' section. Application terms not verified. | G4: =Рейтинг!Q3 -> office@bridgewest.eu | H4: =Рейтинг!R3 -> +44 203 287 0408 (other number shown as '+35 699 699 405' - prefix incomplete, not verified) | I4: =Рейтинг!AE3 -> 4.35
A5: =Рейтинг!A7 -> 6 | B5: =Рейтинг!C7 -> Healy Consultants Group (part of Hawksford) | C5: =Рейтинг!E7 -> https://www.healyconsultants.com | D5: =Рейтинг!H7 -> Да | E5: =Рейтинг!I7&" | "&Рейтинг!J7 -> Dedicated Moldova pages: 10-step incorporation process (name reservation, filing with State Registration Chamber, IDNO, bank account, tax/social registration); LLC with 1 shareholder/1 director any nationality, 12% CIT, ~2 weeks; setup cost quoted in EUR (EUR 7,950 per snippet); 2025 case study of Maltese client registering a recruitment agency in Moldova. Snippet-level only; page fetch failed. | https://www.healyconsultants.com/moldova-company-registration/ ; https://www.healyconsultants.com/moldova-company-registration/client-case-studies/ ; https://www.healyconsultants.com/moldova-company-registration/accounting-legal | F5: =Рейтинг!N7&": "&Рейтинг!O7 -> Не найдена: site search for referral/introducer/partner program returned nothing; no partner page found | G5: =Рейтинг!Q7 -> healy@hawksford.com | H5: =Рейтинг!R7 -> +65 6031 0332 (SG); +971 4266 4470 (Dubai) | I5: =Рейтинг!AE7 -> 4.05
